Workbook
Name IQ_CH: 110000
Name IQ_CQ: 5000
Name IQ_CY: 10000
Name IQ_DAILY: 500000
Name IQ_FH: 100000
Name IQ_FQ: 500
Name IQ_FY: 1000
Name IQ_LTM: 2000
Name IQ_MONTH: 15000
Name IQ_NTM: 6000
Name IQ_WEEK: 50000
Name IQ_YTD: 3000

Sheet Main_Menu
A1: 30/06/2022
E13: ="Risk-free curves as of " & A1 -> Risk-free curves as of 30/06/2022
E15: (annual zero-coupon spot rates)
E17: Basic RFR curves NO volatility adjustment | J17: Basic RFR curves WITH volatility adjustment
E22: Basic RFR curves SCR shock upwards ↑ NO Volatility Adjustment | J22: Basic RFR curves SCR shock upwards ↑ WITH Volatility Adjustment
E27: Basic RFR curves SCR shock downwards ↓ NO Volatility Adjustment | J27: Basic RFR curves SCR shock downwards ↓ WITH Volatility Adjustment
G32: README - Production Notes

Sheet README-Production Notes
A1: 30/06/2022
E12: ="Notes on the Production of the risk-free Term Structures as of " & A1 -> Notes on the Production of the risk-free Term Structures as of 30/06/2022
E15: No issues encountered during the production of the RFR term structures.
E16: Swap data for tenor 1 of CAD and tenor 6 of AUD were not available on the valuation date.

Sheet RFR_spot_no_VA
B2: Main menu | C2: Euro | J2: Denmark | Z2: Norway | AH2: Sweden | AJ2: United Kingdom | AK2: Australia | AM2: Canada | AS2: Japan | BC2: United States
C3: EUR_30_6_2022_SWP_LLP_20_EXT_40_UFR_3.45 | J3: DK_30_6_2022_SWP_LLP_20_EXT_40_UFR_3.45 | Z3: NO_30_6_2022_SWP_LLP_10_EXT_50_UFR_3.45 | AH3: SE_30_6_2022_SWP_LLP_10_EXT_10_UFR_3.45 | AJ3: GB_30_6_2022_SWP_LLP_50_EXT_40_UFR_3.45 | AK3: AU_30_6_2022_SWP_LLP_30_EXT_40_UFR_3.45 | AM3: CA_30_6_2022_SWP_LLP_30_EXT_40_UFR_3.45 | AS3: JP_30_6_2022_GVT_LLP_30_EXT_40_UFR_3.5 | BC3: US_30_6_2022_SWP_LLP_30_EXT_40_UFR_3.45
B4: Coupon_freq | C4: 1 | J4: 1 | Z4: 1 | AH4: 1 | AJ4: 1 | AK4: 2 | AM4: 2 | AS4: 0 | BC4: 2
B5: LLP | C5: 20 | J5: 20 | Z5: 10 | AH5: 10 | AJ5: 50 | AK5: 30 | AM5: 30 | AS5: 30 | BC5: 30
B6: Convergence | C6: 40 | J6: 40 | Z6: 50 | AH6: 10 | AJ6: 40 | AK6: 40 | AM6: 40 | AS6: 40 | BC6: 40
B7: UFR | C7: 3.45 | J7: 3.45 | Z7: 3.45 | AH7: 3.45 | AJ7: 3.45 | AK7: 3.45 | AM7: 3.45 | AS7: 3.5 | BC7: 3.45
B8: alpha | C8: 0.122841 | J8: 0.122948 | Z8: 0.061815 | AH8: 0.378116 | AJ8: 0.12103 | AK8: 0.113507 | AM8: 0.080459 | AS8: 0.118403 | BC8: 0.115116
B9: CRA | C9: 10 | J9: 11 | Z9: 10 | AH9: 10 | AJ9: 0 | AK9: 10 | AM9: 16 | AS9: 0 | BC9: 10
B10: VA
B11: 1 | C11: 0.00736 | J11: 0.00726 | Z11: 0.03092 | AH11: 0.02361 | AJ11: 0.02491 | AK11: 0.03251 | AM11: 0.03392 | AS11: -0.00108 | BC11: 0.03218
B12: 2 | C12: 0.01266 | J12: 0.01256 | Z12: 0.03106 | AH12: 0.02421 | AJ12: 0.02663 | AK12: 0.03638 | AM12: 0.03397 | AS12: -0.00082 | BC12: 0.03208
B13: 3 | C13: 0.01449 | J13: 0.01439 | Z13: 0.03126 | AH13: 0.02504 | AJ13: 0.02626 | AK13: 0.03756 | AM13: 0.03393 | AS13: -0.00064 | BC13: 0.03058
B14: 4 | C14: 0.0161 | J14: 0.016 | Z14: 0.03144 | AH14: 0.02574 | AJ14: 0.02564 | AK14: 0.03839 | AM14: 0.0336 | AS14: -0.00025 | BC14: 0.03015
B15: 5 | C15: 0.01687 | J15: 0.01677 | Z15: 0.03157 | AH15: 0.02619 | AJ15: 0.02518 | AK15: 0.03781 | AM15: 0.03349 | AS15: 0.00036 | BC15: 0.02984
B16: 6 | C16: 0.01782 | J16: 0.01771 | Z16: 0.03164 | AH16: 0.02639 | AJ16: 0.02461 | AK16: 0.03912 | AM16: 0.03379 | AS16: 0.00105 | BC16: 0.02984
B17: 7 | C17: 0.01863 | J17: 0.01853 | Z17: 0.03168 | AH17: 0.0265 | AJ17: 0.02414 | AK17: 0.0406 | AM17: 0.03429 | AS17: 0.00168 | BC17: 0.02983
B18: 8 | C18: 0.01942 | J18: 0.01932 | Z18: 0.03171 | AH18: 0.0266 | AJ18: 0.02384 | AK18: 0.04106 | AM18: 0.03482 | AS18: 0.00223 | BC18: 0.02983
B19: 9 | C19: 0.02017 | J19: 0.02007 | Z19: 0.03174 | AH19: 0.02676 | AJ19: 0.02365 | AK19: 0.04139 | AM19: 0.03526 | AS19: 0.00275 | BC19: 0.02992
B20: 10 | C20: 0.02089 | J20: 0.02079 | Z20: 0.03178 | AH20: 0.027 | AJ20: 0.0236 | AK20: 0.04067 | AM20: 0.03558 | AS20: 0.00332 | BC20: 0.03014
B21: 11 | C21: 0.02178 | J21: 0.02168 | Z21: 0.03182 | AH21: 0.02733 | AJ21: 0.02357 | AK21: 0.04066 | AM21: 0.03576 | AS21: 0.00396 | BC21: 0.03033
B22: 12 | C22: 0.02207 | J22: 0.02197 | Z22: 0.03186 | AH22: 0.02771 | AJ22: 0.02352 | AK22: 0.04102 | AM22: 0.03581 | AS22: 0.00465 | BC22: 0.03052
... B160: 150 | C160: 0.03198 | J160: 0.03196 | Z160: 0.03407 | AH160: 0.03392 | AJ160: 0.02863 | AK160: 0.03406 | AM160: 0.03412 | AS160: 0.02983 | BC160: 0.03255

Sheet RFR_spot_with_VA
B2: Main menu | C2: Euro | J2: Denmark | Z2: Norway | AH2: Sweden | AJ2: United Kingdom | AK2: Australia | AM2: Canada | AS2: Japan | BC2: United States
C3: EUR_30_6_2022_SWP_LLP_20_EXT_40_UFR_3.45 | J3: DK_30_6_2022_SWP_LLP_20_EXT_40_UFR_3.45 | Z3: NO_30_6_2022_SWP_LLP_10_EXT_50_UFR_3.45 | AH3: SE_30_6_2022_SWP_LLP_10_EXT_10_UFR_3.45 | AJ3: GB_30_6_2022_SWP_LLP_50_EXT_40_UFR_3.45 | AK3: AU_30_6_2022_SWP_LLP_30_EXT_40_UFR_3.45 | AM3: CA_30_6_2022_SWP_LLP_30_EXT_40_UFR_3.45 | AS3: JP_30_6_2022_GVT_LLP_30_EXT_40_UFR_3.5 | BC3: US_30_6_2022_SWP_LLP_30_EXT_40_UFR_3.45
B4: Coupon_freq | C4: 1 | J4: 1 | Z4: 1 | AH4: 1 | AJ4: 1 | AK4: 2 | AM4: 2 | AS4: 0 | BC4: 2
B5: LLP | C5: 20 | J5: 20 | Z5: 10 | AH5: 10 | AJ5: 50 | AK5: 30 | AM5: 30 | AS5: 30 | BC5: 30
B6: Convergence | C6: 40 | J6: 40 | Z6: 50 | AH6: 10 | AJ6: 40 | AK6: 40 | AM6: 40 | AS6: 40 | BC6: 40
B7: UFR | C7: 3.45 | J7: 3.45 | Z7: 3.45 | AH7: 3.45 | AJ7: 3.45 | AK7: 3.45 | AM7: 3.45 | AS7: 3.5 | BC7: 3.45
B8: alpha | C8: 0.11905 | J8: 0.117817 | Z8: 0.065649 | AH8: 0.332731 | AJ8: 0.115934 | AK8: 0.106536 | AM8: 0.073808 | AS8: 0.118403 | BC8: 0.103006
B9: CRA | C9: 10 | J9: 11 | Z9: 10 | AH9: 10 | AJ9: 0 | AK9: 10 | AM9: 16 | AS9: 0 | BC9: 10
B10: VA | C10: 25 | D10: n/a | E10: n/a | F10: n/a | G10: n/a | H10: n/a | I10: n/a | J10: 33 | K10: n/a | L10: n/a | M10: n/a | N10: n/a | O10: n/a | P10: n/a | Q10: n/a | R10: n/a | S10: n/a | T10: n/a | U10: n/a | V10: n/a | W10: n/a | X10: n/a | Y10: n/a | Z10: 51 | AA10: n/a | AB10: n/a | AC10: n/a | AD10: n/a | AE10: n/a | AF10: n/a | AG10: n/a | AH10: 19 | AI10: n/a | AJ10: 30 | AK10: 28 | AL10: n/a | AM10: 47 | AN10: n/a | AO10: n/a | AP10: n/a | AQ10: n/a | AR10: n/a | AS10: 0 | AT10: n/a | AU10: n/a | AV10: n/a | AW10: n/a | AX10: n/a | AY10: n/a | AZ10: n/a | BA10: n/a | BB10: n/a | BC10: 47
B11: 1 | C11: 0.00986 | J11: 0.01056 | Z11: 0.03602 | AH11: 0.02551 | AJ11: 0.02791 | AK11: 0.03531 | AM11: 0.03862 | AS11: -0.00108 | BC11: 0.03688
B12: 2 | C12: 0.01516 | J12: 0.01586 | Z12: 0.03616 | AH12: 0.02611 | AJ12: 0.02963 | AK12: 0.03918 | AM12: 0.03867 | AS12: -0.00082 | BC12: 0.03678
B13: 3 | C13: 0.01699 | J13: 0.01769 | Z13: 0.03636 | AH13: 0.02694 | AJ13: 0.02926 | AK13: 0.04036 | AM13: 0.03863 | AS13: -0.00064 | BC13: 0.03528
B14: 4 | C14: 0.0186 | J14: 0.0193 | Z14: 0.03654 | AH14: 0.02764 | AJ14: 0.02864 | AK14: 0.04119 | AM14: 0.0383 | AS14: -0.00025 | BC14: 0.03485
B15: 5 | C15: 0.01937 | J15: 0.02007 | Z15: 0.03667 | AH15: 0.02809 | AJ15: 0.02818 | AK15: 0.04061 | AM15: 0.03819 | AS15: 0.00036 | BC15: 0.03454
B16: 6 | C16: 0.02032 | J16: 0.02101 | Z16: 0.03674 | AH16: 0.02829 | AJ16: 0.02761 | AK16: 0.04192 | AM16: 0.03849 | AS16: 0.00105 | BC16: 0.03454
B17: 7 | C17: 0.02113 | J17: 0.02183 | Z17: 0.03678 | AH17: 0.0284 | AJ17: 0.02714 | AK17: 0.0434 | AM17: 0.03899 | AS17: 0.00168 | BC17: 0.03453
B18: 8 | C18: 0.02192 | J18: 0.02262 | Z18: 0.03681 | AH18: 0.0285 | AJ18: 0.02684 | AK18: 0.04386 | AM18: 0.03952 | AS18: 0.00223 | BC18: 0.03453
B19: 9 | C19: 0.02267 | J19: 0.02337 | Z19: 0.03684 | AH19: 0.02866 | AJ19: 0.02665 | AK19: 0.04419 | AM19: 0.03996 | AS19: 0.00275 | BC19: 0.03462
B20: 10 | C20: 0.02339 | J20: 0.02409 | Z20: 0.03688 | AH20: 0.0289 | AJ20: 0.0266 | AK20: 0.04347 | AM20: 0.04028 | AS20: 0.00332 | BC20: 0.03484
B21: 11 | C21: 0.02428 | J21: 0.02498 | Z21: 0.0369 | AH21: 0.02918 | AJ21: 0.02657 | AK21: 0.04346 | AM21: 0.04046 | AS21: 0.00396 | BC21: 0.03503
B22: 12 | C22: 0.02457 | J22: 0.02527 | Z22: 0.0369 | AH22: 0.02948 | AJ22: 0.02652 | AK22: 0.04382 | AM22: 0.04051 | AS22: 0.00465 | BC22: 0.03522
... B160: 150 | C160: 0.03241 | J160: 0.03253 | Z160: 0.03493 | AH160: 0.03407 | AJ160: 0.02975 | AK160: 0.03474 | AM160: 0.03545 | AS160: 0.02983 | BC160: 0.0337

Sheet Spot_NO_VA_shock_UP
B2: Main menu | C2: =IF(RFR_spot_no_VA!C2="","",RFR_spot_no_VA!C2) -> Euro | D2: =IF(RFR_spot_no_VA!D2="","",RFR_spot_no_VA!D2) | E2: =IF(RFR_spot_no_VA!E2="","",RFR_spot_no_VA!E2) | F2: =IF(RFR_spot_no_VA!F2="","",RFR_spot_no_VA!F2) | G2: =IF(RFR_spot_no_VA!G2="","",RFR_spot_no_VA!G2) | H2: =IF(RFR_spot_no_VA!H2="","",RFR_spot_no_VA!H2) | I2: =IF(RFR_spot_no_VA!I2="","",RFR_spot_no_VA!I2) | J2: =IF(RFR_spot_no_VA!J2="","",RFR_spot_no_VA!J2) -> Denmark | ... BC2: =IF(RFR_spot_no_VA!BC2="","",RFR_spot_no_VA!BC2) -> United States
B3: =IF(RFR_spot_with_VA!B3="","",RFR_spot_with_VA!B3) | C3: =IF(RFR_spot_no_VA!C3="","",RFR_spot_no_VA!C3) -> EUR_30_6_2022_SWP_LLP_20_EXT_40_UFR_3.45 | J3: =IF(RFR_spot_no_VA!J3="","",RFR_spot_no_VA!J3) -> DK_30_6_2022_SWP_LLP_20_EXT_40_UFR_3.45 | Z3: =IF(RFR_spot_no_VA!Z3="","",RFR_spot_no_VA!Z3) -> NO_30_6_2022_SWP_LLP_10_EXT_50_UFR_3.45 | AH3: =IF(RFR_spot_no_VA!AH3="","",RFR_spot_no_VA!AH3) -> SE_30_6_2022_SWP_LLP_10_EXT_10_UFR_3.45 | AJ3: =IF(RFR_spot_no_VA!AJ3="","",RFR_spot_no_VA!AJ3) -> GB_30_6_2022_SWP_LLP_50_EXT_40_UFR_3.45 | AK3: =IF(RFR_spot_no_VA!AK3="","",RFR_spot_no_VA!AK3) -> AU_30_6_2022_SWP_LLP_30_EXT_40_UFR_3.45 | AM3: =IF(RFR_spot_no_VA!AM3="","",RFR_spot_no_VA!AM3) -> CA_30_6_2022_SWP_LLP_30_EXT_40_UFR_3.45 | AS3: =IF(RFR_spot_no_VA!AS3="","",RFR_spot_no_VA!AS3) -> JP_30_6_2022_GVT_LLP_30_EXT_40_UFR_3.5 | BC3: =IF(RFR_spot_no_VA!BC3="","",RFR_spot_no_VA!BC3) -> US_30_6_2022_SWP_LLP_30_EXT_40_UFR_3.45
B4: =IF(RFR_spot_with_VA!B4="","",RFR_spot_with_VA!B4) -> Coupon_freq | C4: =IF(RFR_spot_no_VA!C4="","",RFR_spot_no_VA!C4) -> 1 | J4: =IF(RFR_spot_no_VA!J4="","",RFR_spot_no_VA!J4) -> 1 | Z4: =IF(RFR_spot_no_VA!Z4="","",RFR_spot_no_VA!Z4) -> 1 | AH4: =IF(RFR_spot_no_VA!AH4="","",RFR_spot_no_VA!AH4) -> 1 | AJ4: =IF(RFR_spot_no_VA!AJ4="","",RFR_spot_no_VA!AJ4) -> 1 | AK4: =IF(RFR_spot_no_VA!AK4="","",RFR_spot_no_VA!AK4) -> 2 | AM4: =IF(RFR_spot_no_VA!AM4="","",RFR_spot_no_VA!AM4) -> 2 | AS4: =IF(RFR_spot_no_VA!AS4="","",RFR_spot_no_VA!AS4) -> 0 | BC4: =IF(RFR_spot_no_VA!BC4="","",RFR_spot_no_VA!BC4) -> 2
B5: =IF(RFR_spot_with_VA!B5="","",RFR_spot_with_VA!B5) -> LLP | C5: =IF(RFR_spot_no_VA!C5="","",RFR_spot_no_VA!C5) -> 20 | J5: =IF(RFR_spot_no_VA!J5="","",RFR_spot_no_VA!J5) -> 20 | Z5: =IF(RFR_spot_no_VA!Z5="","",RFR_spot_no_VA!Z5) -> 10 | AH5: =IF(RFR_spot_no_VA!AH5="","",RFR_spot_no_VA!AH5) -> 10 | AJ5: =IF(RFR_spot_no_VA!AJ5="","",RFR_spot_no_VA!AJ5) -> 50 | AK5: =IF(RFR_spot_no_VA!AK5="","",RFR_spot_no_VA!AK5) -> 30 | AM5: =IF(RFR_spot_no_VA!AM5="","",RFR_spot_no_VA!AM5) -> 30 | AS5: =IF(RFR_spot_no_VA!AS5="","",RFR_spot_no_VA!AS5) -> 30 | BC5: =IF(RFR_spot_no_VA!BC5="","",RFR_spot_no_VA!BC5) -> 30
B6: =IF(RFR_spot_with_VA!B6="","",RFR_spot_with_VA!B6) -> Convergence | C6: =IF(RFR_spot_no_VA!C6="","",RFR_spot_no_VA!C6) -> 40 | J6: =IF(RFR_spot_no_VA!J6="","",RFR_spot_no_VA!J6) -> 40 | Z6: =IF(RFR_spot_no_VA!Z6="","",RFR_spot_no_VA!Z6) -> 50 | AH6: =IF(RFR_spot_no_VA!AH6="","",RFR_spot_no_VA!AH6) -> 10 | AJ6: =IF(RFR_spot_no_VA!AJ6="","",RFR_spot_no_VA!AJ6) -> 40 | AK6: =IF(RFR_spot_no_VA!AK6="","",RFR_spot_no_VA!AK6) -> 40 | AM6: =IF(RFR_spot_no_VA!AM6="","",RFR_spot_no_VA!AM6) -> 40 | AS6: =IF(RFR_spot_no_VA!AS6="","",RFR_spot_no_VA!AS6) -> 40 | BC6: =IF(RFR_spot_no_VA!BC6="","",RFR_spot_no_VA!BC6) -> 40
B7: =IF(RFR_spot_with_VA!B7="","",RFR_spot_with_VA!B7) -> UFR | C7: =IF(RFR_spot_no_VA!C7="","",RFR_spot_no_VA!C7) -> 3.45 | J7: =IF(RFR_spot_no_VA!J7="","",RFR_spot_no_VA!J7) -> 3.45 | Z7: =IF(RFR_spot_no_VA!Z7="","",RFR_spot_no_VA!Z7) -> 3.45 | AH7: =IF(RFR_spot_no_VA!AH7="","",RFR_spot_no_VA!AH7) -> 3.45 | AJ7: =IF(RFR_spot_no_VA!AJ7="","",RFR_spot_no_VA!AJ7) -> 3.45 | AK7: =IF(RFR_spot_no_VA!AK7="","",RFR_spot_no_VA!AK7) -> 3.45 | AM7: =IF(RFR_spot_no_VA!AM7="","",RFR_spot_no_VA!AM7) -> 3.45 | AS7: =IF(RFR_spot_no_VA!AS7="","",RFR_spot_no_VA!AS7) -> 3.5 | BC7: =IF(RFR_spot_no_VA!BC7="","",RFR_spot_no_VA!BC7) -> 3.45
B9: =IF(RFR_spot_with_VA!B9="","",RFR_spot_with_VA!B9) -> CRA | C9: =IF(RFR_spot_no_VA!C9="","",RFR_spot_no_VA!C9) -> 10 | J9: =IF(RFR_spot_no_VA!J9="","",RFR_spot_no_VA!J9) -> 11 | Z9: =IF(RFR_spot_no_VA!Z9="","",RFR_spot_no_VA!Z9) -> 10 | AH9: =IF(RFR_spot_no_VA!AH9="","",RFR_spot_no_VA!AH9) -> 10 | AJ9: =IF(RFR_spot_no_VA!AJ9="","",RFR_spot_no_VA!AJ9) -> 0 | AK9: =IF(RFR_spot_no_VA!AK9="","",RFR_spot_no_VA!AK9) -> 10 | AM9: =IF(RFR_spot_no_VA!AM9="","",RFR_spot_no_VA!AM9) -> 16 | AS9: =IF(RFR_spot_no_VA!AS9="","",RFR_spot_no_VA!AS9) -> 0 | BC9: =IF(RFR_spot_no_VA!BC9="","",RFR_spot_no_VA!BC9) -> 10
B10: =IF(RFR_spot_with_VA!B10="","",RFR_spot_with_VA!B10) -> VA | C10: =IF(RFR_spot_no_VA!C10="","",RFR_spot_no_VA!C10) | J10: =IF(RFR_spot_no_VA!J10="","",RFR_spot_no_VA!J10) | Z10: =IF(RFR_spot_no_VA!Z10="","",RFR_spot_no_VA!Z10) | AH10: =IF(RFR_spot_no_VA!AH10="","",RFR_spot_no_VA!AH10) | AJ10: =IF(RFR_spot_no_VA!AJ10="","",RFR_spot_no_VA!AJ10) | AK10: =IF(RFR_spot_no_VA!AK10="","",RFR_spot_no_VA!AK10) | AM10: =IF(RFR_spot_no_VA!AM10="","",RFR_spot_no_VA!AM10) | AS10: =IF(RFR_spot_no_VA!AS10="","",RFR_spot_no_VA!AS10) | BC10: =IF(RFR_spot_no_VA!BC10="","",RFR_spot_no_VA!BC10)
B11: =RFR_spot_no_VA!B11 -> 1 | C11: =ROUND(RFR_spot_no_VA!C11 + MAX(0.01,Shocks!$E11*ABS(RFR_spot_no_VA!C11) ),5) -> 0.01736 | J11: =ROUND(RFR_spot_no_VA!J11 + MAX(0.01,Shocks!$E11*ABS(RFR_spot_no_VA!J11) ),5) -> 0.01726 | Z11: =ROUND(RFR_spot_no_VA!Z11 + MAX(0.01,Shocks!$E11*ABS(RFR_spot_no_VA!Z11) ),5) -> 0.05256 | AH11: =ROUND(RFR_spot_no_VA!AH11 + MAX(0.01,Shocks!$E11*ABS(RFR_spot_no_VA!AH11) ),5) -> 0.04014 | AJ11: =ROUND(RFR_spot_no_VA!AJ11 + MAX(0.01,Shocks!$E11*ABS(RFR_spot_no_VA!AJ11) ),5) -> 0.04235 | AK11: =ROUND(RFR_spot_no_VA!AK11 + MAX(0.01,Shocks!$E11*ABS(RFR_spot_no_VA!AK11) ),5) -> 0.05527 | AM11: =ROUND(RFR_spot_no_VA!AM11 + MAX(0.01,Shocks!$E11*ABS(RFR_spot_no_VA!AM11) ),5) -> 0.05766 | AS11: =ROUND(RFR_spot_no_VA!AS11 + MAX(0.01,Shocks!$E11*ABS(RFR_spot_no_VA!AS11) ),5) -> 0.00892 | BC11: =ROUND(RFR_spot_no_VA!BC11 + MAX(0.01,Shocks!$E11*ABS(RFR_spot_no_VA!BC11) ),5) -> 0.05471
B12: =RFR_spot_no_VA!B12 -> 2 | C12: =ROUND(RFR_spot_no_VA!C12 + MAX(0.01,Shocks!$E12*ABS(RFR_spot_no_VA!C12) ),5) -> 0.02266 | J12: =ROUND(RFR_spot_no_VA!J12 + MAX(0.01,Shocks!$E12*ABS(RFR_spot_no_VA!J12) ),5) -> 0.02256 | Z12: =ROUND(RFR_spot_no_VA!Z12 + MAX(0.01,Shocks!$E12*ABS(RFR_spot_no_VA!Z12) ),5) -> 0.0528 | AH12: =ROUND(RFR_spot_no_VA!AH12 + MAX(0.01,Shocks!$E12*ABS(RFR_spot_no_VA!AH12) ),5) -> 0.04116 | AJ12: =ROUND(RFR_spot_no_VA!AJ12 + MAX(0.01,Shocks!$E12*ABS(RFR_spot_no_VA!AJ12) ),5) -> 0.04527 | AK12: =ROUND(RFR_spot_no_VA!AK12 + MAX(0.01,Shocks!$E12*ABS(RFR_spot_no_VA!AK12) ),5) -> 0.06185 | AM12: =ROUND(RFR_spot_no_VA!AM12 + MAX(0.01,Shocks!$E12*ABS(RFR_spot_no_VA!AM12) ),5) -> 0.05775 | AS12: =ROUND(RFR_spot_no_VA!AS12 + MAX(0.01,Shocks!$E12*ABS(RFR_spot_no_VA!AS12) ),5) -> 0.00918 | BC12: =ROUND(RFR_spot_no_VA!BC12 + MAX(0.01,Shocks!$E12*ABS(RFR_spot_no_VA!BC12) ),5) -> 0.05454
B13: =RFR_spot_no_VA!B13 -> 3 | C13: =ROUND(RFR_spot_no_VA!C13 + MAX(0.01,Shocks!$E13*ABS(RFR_spot_no_VA!C13) ),5) -> 0.02449 | J13: =ROUND(RFR_spot_no_VA!J13 + MAX(0.01,Shocks!$E13*ABS(RFR_spot_no_VA!J13) ),5) -> 0.02439 | Z13: =ROUND(RFR_spot_no_VA!Z13 + MAX(0.01,Shocks!$E13*ABS(RFR_spot_no_VA!Z13) ),5) -> 0.05127 | AH13: =ROUND(RFR_spot_no_VA!AH13 + MAX(0.01,Shocks!$E13*ABS(RFR_spot_no_VA!AH13) ),5) -> 0.04107 | AJ13: =ROUND(RFR_spot_no_VA!AJ13 + MAX(0.01,Shocks!$E13*ABS(RFR_spot_no_VA!AJ13) ),5) -> 0.04307 | AK13: =ROUND(RFR_spot_no_VA!AK13 + MAX(0.01,Shocks!$E13*ABS(RFR_spot_no_VA!AK13) ),5) -> 0.0616 | AM13: =ROUND(RFR_spot_no_VA!AM13 + MAX(0.01,Shocks!$E13*ABS(RFR_spot_no_VA!AM13) ),5) -> 0.05565 | AS13: =ROUND(RFR_spot_no_VA!AS13 + MAX(0.01,Shocks!$E13*ABS(RFR_spot_no_VA!AS13) ),5) -> 0.00936 | BC13: =ROUND(RFR_spot_no_VA!BC13 + MAX(0.01,Shocks!$E13*ABS(RFR_spot_no_VA!BC13) ),5) -> 0.05015
B14: =RFR_spot_no_VA!B14 -> 4 | C14: =ROUND(RFR_spot_no_VA!C14 + MAX(0.01,Shocks!$E14*ABS(RFR_spot_no_VA!C14) ),5) -> 0.0261 | J14: =ROUND(RFR_spot_no_VA!J14 + MAX(0.01,Shocks!$E14*ABS(RFR_spot_no_VA!J14) ),5) -> 0.026 | Z14: =ROUND(RFR_spot_no_VA!Z14 + MAX(0.01,Shocks!$E14*ABS(RFR_spot_no_VA!Z14) ),5) -> 0.04999 | AH14: =ROUND(RFR_spot_no_VA!AH14 + MAX(0.01,Shocks!$E14*ABS(RFR_spot_no_VA!AH14) ),5) -> 0.04093 | AJ14: =ROUND(RFR_spot_no_VA!AJ14 + MAX(0.01,Shocks!$E14*ABS(RFR_spot_no_VA!AJ14) ),5) -> 0.04077 | AK14: =ROUND(RFR_spot_no_VA!AK14 + MAX(0.01,Shocks!$E14*ABS(RFR_spot_no_VA!AK14) ),5) -> 0.06104 | AM14: =ROUND(RFR_spot_no_VA!AM14 + MAX(0.01,Shocks!$E14*ABS(RFR_spot_no_VA!AM14) ),5) -> 0.05342 | AS14: =ROUND(RFR_spot_no_VA!AS14 + MAX(0.01,Shocks!$E14*ABS(RFR_spot_no_VA!AS14) ),5) -> 0.00975 | BC14: =ROUND(RFR_spot_no_VA!BC14 + MAX(0.01,Shocks!$E14*ABS(RFR_spot_no_VA!BC14) ),5) -> 0.04794
B15: =RFR_spot_no_VA!B15 -> 5 | C15: =ROUND(RFR_spot_no_VA!C15 + MAX(0.01,Shocks!$E15*ABS(RFR_spot_no_VA!C15) ),5) -> 0.02687 | J15: =ROUND(RFR_spot_no_VA!J15 + MAX(0.01,Shocks!$E15*ABS(RFR_spot_no_VA!J15) ),5) -> 0.02677 | Z15: =ROUND(RFR_spot_no_VA!Z15 + MAX(0.01,Shocks!$E15*ABS(RFR_spot_no_VA!Z15) ),5) -> 0.04893 | AH15: =ROUND(RFR_spot_no_VA!AH15 + MAX(0.01,Shocks!$E15*ABS(RFR_spot_no_VA!AH15) ),5) -> 0.04059 | AJ15: =ROUND(RFR_spot_no_VA!AJ15 + MAX(0.01,Shocks!$E15*ABS(RFR_spot_no_VA!AJ15) ),5) -> 0.03903 | AK15: =ROUND(RFR_spot_no_VA!AK15 + MAX(0.01,Shocks!$E15*ABS(RFR_spot_no_VA!AK15) ),5) -> 0.05861 | AM15: =ROUND(RFR_spot_no_VA!AM15 + MAX(0.01,Shocks!$E15*ABS(RFR_spot_no_VA!AM15) ),5) -> 0.05191 | AS15: =ROUND(RFR_spot_no_VA!AS15 + MAX(0.01,Shocks!$E15*ABS(RFR_spot_no_VA!AS15) ),5) -> 0.01036 | BC15: =ROUND(RFR_spot_no_VA!BC15 + MAX(0.01,Shocks!$E15*ABS(RFR_spot_no_VA!BC15) ),5) -> 0.04625
B16: =RFR_spot_no_VA!B16 -> 6 | C16: =ROUND(RFR_spot_no_VA!C16 + MAX(0.01,Shocks!$E16*ABS(RFR_spot_no_VA!C16) ),5) -> 0.02782 | J16: =ROUND(RFR_spot_no_VA!J16 + MAX(0.01,Shocks!$E16*ABS(RFR_spot_no_VA!J16) ),5) -> 0.02771 | Z16: =ROUND(RFR_spot_no_VA!Z16 + MAX(0.01,Shocks!$E16*ABS(RFR_spot_no_VA!Z16) ),5) -> 0.04809 | AH16: =ROUND(RFR_spot_no_VA!AH16 + MAX(0.01,Shocks!$E16*ABS(RFR_spot_no_VA!AH16) ),5) -> 0.04011 | AJ16: =ROUND(RFR_spot_no_VA!AJ16 + MAX(0.01,Shocks!$E16*ABS(RFR_spot_no_VA!AJ16) ),5) -> 0.03741 | AK16: =ROUND(RFR_spot_no_VA!AK16 + MAX(0.01,Shocks!$E16*ABS(RFR_spot_no_VA!AK16) ),5) -> 0.05946 | AM16: =ROUND(RFR_spot_no_VA!AM16 + MAX(0.01,Shocks!$E16*ABS(RFR_spot_no_VA!AM16) ),5) -> 0.05136 | AS16: =ROUND(RFR_spot_no_VA!AS16 + MAX(0.01,Shocks!$E16*ABS(RFR_spot_no_VA!AS16) ),5) -> 0.01105 | BC16: =ROUND(RFR_spot_no_VA!BC16 + MAX(0.01,Shocks!$E16*ABS(RFR_spot_no_VA!BC16) ),5) -> 0.04536
B17: =RFR_spot_no_VA!B17 -> 7 | C17: =ROUND(RFR_spot_no_VA!C17 + MAX(0.01,Shocks!$E17*ABS(RFR_spot_no_VA!C17) ),5) -> 0.02863 | J17: =ROUND(RFR_spot_no_VA!J17 + MAX(0.01,Shocks!$E17*ABS(RFR_spot_no_VA!J17) ),5) -> 0.02853 | Z17: =ROUND(RFR_spot_no_VA!Z17 + MAX(0.01,Shocks!$E17*ABS(RFR_spot_no_VA!Z17) ),5) -> 0.0472 | AH17: =ROUND(RFR_spot_no_VA!AH17 + MAX(0.01,Shocks!$E17*ABS(RFR_spot_no_VA!AH17) ),5) -> 0.03949 | AJ17: =ROUND(RFR_spot_no_VA!AJ17 + MAX(0.01,Shocks!$E17*ABS(RFR_spot_no_VA!AJ17) ),5) -> 0.03597 | AK17: =ROUND(RFR_spot_no_VA!AK17 + MAX(0.01,Shocks!$E17*ABS(RFR_spot_no_VA!AK17) ),5) -> 0.06049 | AM17: =ROUND(RFR_spot_no_VA!AM17 + MAX(0.01,Shocks!$E17*ABS(RFR_spot_no_VA!AM17) ),5) -> 0.05109 | AS17: =ROUND(RFR_spot_no_VA!AS17 + MAX(0.01,Shocks!$E17*ABS(RFR_spot_no_VA!AS17) ),5) -> 0.01168 | BC17: =ROUND(RFR_spot_no_VA!BC17 + MAX(0.01,Shocks!$E17*ABS(RFR_spot_no_VA!BC17) ),5) -> 0.04445
B18: =RFR_spot_no_VA!B18 -> 8 | C18: =ROUND(RFR_spot_no_VA!C18 + MAX(0.01,Shocks!$E18*ABS(RFR_spot_no_VA!C18) ),5) -> 0.02942 | J18: =ROUND(RFR_spot_no_VA!J18 + MAX(0.01,Shocks!$E18*ABS(RFR_spot_no_VA!J18) ),5) -> 0.02932 | Z18: =ROUND(RFR_spot_no_VA!Z18 + MAX(0.01,Shocks!$E18*ABS(RFR_spot_no_VA!Z18) ),5) -> 0.04661 | AH18: =ROUND(RFR_spot_no_VA!AH18 + MAX(0.01,Shocks!$E18*ABS(RFR_spot_no_VA!AH18) ),5) -> 0.0391 | AJ18: =ROUND(RFR_spot_no_VA!AJ18 + MAX(0.01,Shocks!$E18*ABS(RFR_spot_no_VA!AJ18) ),5) -> 0.03504 | AK18: =ROUND(RFR_spot_no_VA!AK18 + MAX(0.01,Shocks!$E18*ABS(RFR_spot_no_VA!AK18) ),5) -> 0.06036 | AM18: =ROUND(RFR_spot_no_VA!AM18 + MAX(0.01,Shocks!$E18*ABS(RFR_spot_no_VA!AM18) ),5) -> 0.05119 | AS18: =ROUND(RFR_spot_no_VA!AS18 + MAX(0.01,Shocks!$E18*ABS(RFR_spot_no_VA!AS18) ),5) -> 0.01223 | BC18: =ROUND(RFR_spot_no_VA!BC18 + MAX(0.01,Shocks!$E18*ABS(RFR_spot_no_VA!BC18) ),5) -> 0.04385
B19: =RFR_spot_no_VA!B19 -> 9 | C19: =ROUND(RFR_spot_no_VA!C19 + MAX(0.01,Shocks!$E19*ABS(RFR_spot_no_VA!C19) ),5) -> 0.03017 | J19: =ROUND(RFR_spot_no_VA!J19 + MAX(0.01,Shocks!$E19*ABS(RFR_spot_no_VA!J19) ),5) -> 0.03007 | Z19: =ROUND(RFR_spot_no_VA!Z19 + MAX(0.01,Shocks!$E19*ABS(RFR_spot_no_VA!Z19) ),5) -> 0.04571 | AH19: =ROUND(RFR_spot_no_VA!AH19 + MAX(0.01,Shocks!$E19*ABS(RFR_spot_no_VA!AH19) ),5) -> 0.03853 | AJ19: =ROUND(RFR_spot_no_VA!AJ19 + MAX(0.01,Shocks!$E19*ABS(RFR_spot_no_VA!AJ19) ),5) -> 0.03406 | AK19: =ROUND(RFR_spot_no_VA!AK19 + MAX(0.01,Shocks!$E19*ABS(RFR_spot_no_VA!AK19) ),5) -> 0.0596 | AM19: =ROUND(RFR_spot_no_VA!AM19 + MAX(0.01,Shocks!$E19*ABS(RFR_spot_no_VA!AM19) ),5) -> 0.05077 | AS19: =ROUND(RFR_spot_no_VA!AS19 + MAX(0.01,Shocks!$E19*ABS(RFR_spot_no_VA!AS19) ),5) -> 0.01275 | BC19: =ROUND(RFR_spot_no_VA!BC19 + MAX(0.01,Shocks!$E19*ABS(RFR_spot_no_VA!BC19) ),5) -> 0.04308
B20: =RFR_spot_no_VA!B20 -> 10 | C20: =ROUND(RFR_spot_no_VA!C20 + MAX(0.01,Shocks!$E20*ABS(RFR_spot_no_VA!C20) ),5) -> 0.03089 | J20: =ROUND(RFR_spot_no_VA!J20 + MAX(0.01,Shocks!$E20*ABS(RFR_spot_no_VA!J20) ),5) -> 0.03079 | Z20: =ROUND(RFR_spot_no_VA!Z20 + MAX(0.01,Shocks!$E20*ABS(RFR_spot_no_VA!Z20) ),5) -> 0.04513 | AH20: =ROUND(RFR_spot_no_VA!AH20 + MAX(0.01,Shocks!$E20*ABS(RFR_spot_no_VA!AH20) ),5) -> 0.03834 | AJ20: =ROUND(RFR_spot_no_VA!AJ20 + MAX(0.01,Shocks!$E20*ABS(RFR_spot_no_VA!AJ20) ),5) -> 0.0336 | AK20: =ROUND(RFR_spot_no_VA!AK20 + MAX(0.01,Shocks!$E20*ABS(RFR_spot_no_VA!AK20) ),5) -> 0.05775 | AM20: =ROUND(RFR_spot_no_VA!AM20 + MAX(0.01,Shocks!$E20*ABS(RFR_spot_no_VA!AM20) ),5) -> 0.05052 | AS20: =ROUND(RFR_spot_no_VA!AS20 + MAX(0.01,Shocks!$E20*ABS(RFR_spot_no_VA!AS20) ),5) -> 0.01332 | BC20: =ROUND(RFR_spot_no_VA!BC20 + MAX(0.01,Shocks!$E20*ABS(RFR_spot_no_VA!BC20) ),5) -> 0.0428
B21: =RFR_spot_no_VA!B21 -> 11 | C21: =ROUND(RFR_spot_no_VA!C21 + MAX(0.01,Shocks!$E21*ABS(RFR_spot_no_VA!C21) ),5) -> 0.03178 | J21: =ROUND(RFR_spot_no_VA!J21 + MAX(0.01,Shocks!$E21*ABS(RFR_spot_no_VA!J21) ),5) -> 0.03168 | Z21: =ROUND(RFR_spot_no_VA!Z21 + MAX(0.01,Shocks!$E21*ABS(RFR_spot_no_VA!Z21) ),5) -> 0.04423 | AH21: =ROUND(RFR_spot_no_VA!AH21 + MAX(0.01,Shocks!$E21*ABS(RFR_spot_no_VA!AH21) ),5) -> 0.03799 | AJ21: =ROUND(RFR_spot_no_VA!AJ21 + MAX(0.01,Shocks!$E21*ABS(RFR_spot_no_VA!AJ21) ),5) -> 0.03357 | AK21: =ROUND(RFR_spot_no_VA!AK21 + MAX(0.01,Shocks!$E21*ABS(RFR_spot_no_VA!AK21) ),5) -> 0.05652 | AM21: =ROUND(RFR_spot_no_VA!AM21 + MAX(0.01,Shocks!$E21*ABS(RFR_spot_no_VA!AM21) ),5) -> 0.04971 | AS21: =ROUND(RFR_spot_no_VA!AS21 + MAX(0.01,Shocks!$E21*ABS(RFR_spot_no_VA!AS21) ),5) -> 0.01396 | BC21: =ROUND(RFR_spot_no_VA!BC21 + MAX(0.01,Shocks!$E21*ABS(RFR_spot_no_VA!BC21) ),5) -> 0.04216
B22: =RFR_spot_no_VA!B22 -> 12 | C22: =ROUND(RFR_spot_no_VA!C22 + MAX(0.01,Shocks!$E22*ABS(RFR_spot_no_VA!C22) ),5) -> 0.03207 | J22: =ROUND(RFR_spot_no_VA!J22 + MAX(0.01,Shocks!$E22*ABS(RFR_spot_no_VA!J22) ),5) -> 0.03197 | Z22: =ROUND(RFR_spot_no_VA!Z22 + MAX(0.01,Shocks!$E22*ABS(RFR_spot_no_VA!Z22) ),5) -> 0.04365 | AH22: =ROUND(RFR_spot_no_VA!AH22 + MAX(0.01,Shocks!$E22*ABS(RFR_spot_no_VA!AH22) ),5) -> 0.03796 | AJ22: =ROUND(RFR_spot_no_VA!AJ22 + MAX(0.01,Shocks!$E22*ABS(RFR_spot_no_VA!AJ22) ),5) -> 0.03352 | AK22: =ROUND(RFR_spot_no_VA!AK22 + MAX(0.01,Shocks!$E22*ABS(RFR_spot_no_VA!AK22) ),5) -> 0.0562 | AM22: =ROUND(RFR_spot_no_VA!AM22 + MAX(0.01,Shocks!$E22*ABS(RFR_spot_no_VA!AM22) ),5) -> 0.04906 | AS22: =ROUND(RFR_spot_no_VA!AS22 + MAX(0.01,Shocks!$E22*ABS(RFR_spot_no_VA!AS22) ),5) -> 0.01465 | BC22: =ROUND(RFR_spot_no_VA!BC22 + MAX(0.01,Shocks!$E22*ABS(RFR_spot_no_VA!BC22) ),5) -> 0.04181
... B160: =RFR_spot_no_VA!B160 -> 150 | C160: =ROUND(RFR_spot_no_VA!C160 + MAX(0.01,Shocks!$E160*ABS(RFR_spot_no_VA!C160) ),5) -> 0.04198 | J160: =ROUND(RFR_spot_no_VA!J160 + MAX(0.01,Shocks!$E160*ABS(RFR_spot_no_VA!J160) ),5) -> 0.04196 | Z160: =ROUND(RFR_spot_no_VA!Z160 + MAX(0.01,Shocks!$E160*ABS(RFR_spot_no_VA!Z160) ),5) -> 0.04407 | AH160: =ROUND(RFR_spot_no_VA!AH160 + MAX(0.01,Shocks!$E160*ABS(RFR_spot_no_VA!AH160) ),5) -> 0.04392 | AJ160: =ROUND(RFR_spot_no_VA!AJ160 + MAX(0.01,Shocks!$E160*ABS(RFR_spot_no_VA!AJ160) ),5) -> 0.03863 | AK160: =ROUND(RFR_spot_no_VA!AK160 + MAX(0.01,Shocks!$E160*ABS(RFR_spot_no_VA!AK160) ),5) -> 0.04406 | AM160: =ROUND(RFR_spot_no_VA!AM160 + MAX(0.01,Shocks!$E160*ABS(RFR_spot_no_VA!AM160) ),5) -> 0.04412 | AS160: =ROUND(RFR_spot_no_VA!AS160 + MAX(0.01,Shocks!$E160*ABS(RFR_spot_no_VA!AS160) ),5) -> 0.03983 | BC160: =ROUND(RFR_spot_no_VA!BC160 + MAX(0.01,Shocks!$E160*ABS(RFR_spot_no_VA!BC160) ),5) -> 0.04255

Sheet Spot_NO_VA_shock_DOWN
B2: Main menu | C2: =IF(RFR_spot_no_VA!C2="","",RFR_spot_no_VA!C2) -> Euro | D2: =IF(RFR_spot_no_VA!D2="","",RFR_spot_no_VA!D2) | E2: =IF(RFR_spot_no_VA!E2="","",RFR_spot_no_VA!E2) | F2: =IF(RFR_spot_no_VA!F2="","",RFR_spot_no_VA!F2) | G2: =IF(RFR_spot_no_VA!G2="","",RFR_spot_no_VA!G2) | H2: =IF(RFR_spot_no_VA!H2="","",RFR_spot_no_VA!H2) | I2: =IF(RFR_spot_no_VA!I2="","",RFR_spot_no_VA!I2) | J2: =IF(RFR_spot_no_VA!J2="","",RFR_spot_no_VA!J2) -> Denmark | ... BC2: =IF(RFR_spot_no_VA!BC2="","",RFR_spot_no_VA!BC2) -> United States
B3: =IF(RFR_spot_with_VA!B3="","",RFR_spot_with_VA!B3) | C3: =IF(RFR_spot_no_VA!C3="","",RFR_spot_no_VA!C3) -> EUR_30_6_2022_SWP_LLP_20_EXT_40_UFR_3.45 | J3: =IF(RFR_spot_no_VA!J3="","",RFR_spot_no_VA!J3) -> DK_30_6_2022_SWP_LLP_20_EXT_40_UFR_3.45 | Z3: =IF(RFR_spot_no_VA!Z3="","",RFR_spot_no_VA!Z3) -> NO_30_6_2022_SWP_LLP_10_EXT_50_UFR_3.45 | AH3: =IF(RFR_spot_no_VA!AH3="","",RFR_spot_no_VA!AH3) -> SE_30_6_2022_SWP_LLP_10_EXT_10_UFR_3.45 | AJ3: =IF(RFR_spot_no_VA!AJ3="","",RFR_spot_no_VA!AJ3) -> GB_30_6_2022_SWP_LLP_50_EXT_40_UFR_3.45 | AK3: =IF(RFR_spot_no_VA!AK3="","",RFR_spot_no_VA!AK3) -> AU_30_6_2022_SWP_LLP_30_EXT_40_UFR_3.45 | AM3: =IF(RFR_spot_no_VA!AM3="","",RFR_spot_no_VA!AM3) -> CA_30_6_2022_SWP_LLP_30_EXT_40_UFR_3.45 | AS3: =IF(RFR_spot_no_VA!AS3="","",RFR_spot_no_VA!AS3) -> JP_30_6_2022_GVT_LLP_30_EXT_40_UFR_3.5 | BC3: =IF(RFR_spot_no_VA!BC3="","",RFR_spot_no_VA!BC3) -> US_30_6_2022_SWP_LLP_30_EXT_40_UFR_3.45
B4: =IF(RFR_spot_with_VA!B4="","",RFR_spot_with_VA!B4) -> Coupon_freq | C4: =IF(RFR_spot_no_VA!C4="","",RFR_spot_no_VA!C4) -> 1 | J4: =IF(RFR_spot_no_VA!J4="","",RFR_spot_no_VA!J4) -> 1 | Z4: =IF(RFR_spot_no_VA!Z4="","",RFR_spot_no_VA!Z4) -> 1 | AH4: =IF(RFR_spot_no_VA!AH4="","",RFR_spot_no_VA!AH4) -> 1 | AJ4: =IF(RFR_spot_no_VA!AJ4="","",RFR_spot_no_VA!AJ4) -> 1 | AK4: =IF(RFR_spot_no_VA!AK4="","",RFR_spot_no_VA!AK4) -> 2 | AM4: =IF(RFR_spot_no_VA!AM4="","",RFR_spot_no_VA!AM4) -> 2 | AS4: =IF(RFR_spot_no_VA!AS4="","",RFR_spot_no_VA!AS4) -> 0 | BC4: =IF(RFR_spot_no_VA!BC4="","",RFR_spot_no_VA!BC4) -> 2
B5: =IF(RFR_spot_with_VA!B5="","",RFR_spot_with_VA!B5) -> LLP | C5: =IF(RFR_spot_no_VA!C5="","",RFR_spot_no_VA!C5) -> 20 | J5: =IF(RFR_spot_no_VA!J5="","",RFR_spot_no_VA!J5) -> 20 | Z5: =IF(RFR_spot_no_VA!Z5="","",RFR_spot_no_VA!Z5) -> 10 | AH5: =IF(RFR_spot_no_VA!AH5="","",RFR_spot_no_VA!AH5) -> 10 | AJ5: =IF(RFR_spot_no_VA!AJ5="","",RFR_spot_no_VA!AJ5) -> 50 | AK5: =IF(RFR_spot_no_VA!AK5="","",RFR_spot_no_VA!AK5) -> 30 | AM5: =IF(RFR_spot_no_VA!AM5="","",RFR_spot_no_VA!AM5) -> 30 | AS5: =IF(RFR_spot_no_VA!AS5="","",RFR_spot_no_VA!AS5) -> 30 | BC5: =IF(RFR_spot_no_VA!BC5="","",RFR_spot_no_VA!BC5) -> 30
B6: =IF(RFR_spot_with_VA!B6="","",RFR_spot_with_VA!B6) -> Convergence | C6: =IF(RFR_spot_no_VA!C6="","",RFR_spot_no_VA!C6) -> 40 | J6: =IF(RFR_spot_no_VA!J6="","",RFR_spot_no_VA!J6) -> 40 | Z6: =IF(RFR_spot_no_VA!Z6="","",RFR_spot_no_VA!Z6) -> 50 | AH6: =IF(RFR_spot_no_VA!AH6="","",RFR_spot_no_VA!AH6) -> 10 | AJ6: =IF(RFR_spot_no_VA!AJ6="","",RFR_spot_no_VA!AJ6) -> 40 | AK6: =IF(RFR_spot_no_VA!AK6="","",RFR_spot_no_VA!AK6) -> 40 | AM6: =IF(RFR_spot_no_VA!AM6="","",RFR_spot_no_VA!AM6) -> 40 | AS6: =IF(RFR_spot_no_VA!AS6="","",RFR_spot_no_VA!AS6) -> 40 | BC6: =IF(RFR_spot_no_VA!BC6="","",RFR_spot_no_VA!BC6) -> 40
B7: =IF(RFR_spot_with_VA!B7="","",RFR_spot_with_VA!B7) -> UFR | C7: =IF(RFR_spot_no_VA!C7="","",RFR_spot_no_VA!C7) -> 3.45 | J7: =IF(RFR_spot_no_VA!J7="","",RFR_spot_no_VA!J7) -> 3.45 | Z7: =IF(RFR_spot_no_VA!Z7="","",RFR_spot_no_VA!Z7) -> 3.45 | AH7: =IF(RFR_spot_no_VA!AH7="","",RFR_spot_no_VA!AH7) -> 3.45 | AJ7: =IF(RFR_spot_no_VA!AJ7="","",RFR_spot_no_VA!AJ7) -> 3.45 | AK7: =IF(RFR_spot_no_VA!AK7="","",RFR_spot_no_VA!AK7) -> 3.45 | AM7: =IF(RFR_spot_no_VA!AM7="","",RFR_spot_no_VA!AM7) -> 3.45 | AS7: =IF(RFR_spot_no_VA!AS7="","",RFR_spot_no_VA!AS7) -> 3.5 | BC7: =IF(RFR_spot_no_VA!BC7="","",RFR_spot_no_VA!BC7) -> 3.45
B9: =IF(RFR_spot_with_VA!B9="","",RFR_spot_with_VA!B9) -> CRA | C9: =IF(RFR_spot_no_VA!C9="","",RFR_spot_no_VA!C9) -> 10 | J9: =IF(RFR_spot_no_VA!J9="","",RFR_spot_no_VA!J9) -> 11 | Z9: =IF(RFR_spot_no_VA!Z9="","",RFR_spot_no_VA!Z9) -> 10 | AH9: =IF(RFR_spot_no_VA!AH9="","",RFR_spot_no_VA!AH9) -> 10 | AJ9: =IF(RFR_spot_no_VA!AJ9="","",RFR_spot_no_VA!AJ9) -> 0 | AK9: =IF(RFR_spot_no_VA!AK9="","",RFR_spot_no_VA!AK9) -> 10 | AM9: =IF(RFR_spot_no_VA!AM9="","",RFR_spot_no_VA!AM9) -> 16 | AS9: =IF(RFR_spot_no_VA!AS9="","",RFR_spot_no_VA!AS9) -> 0 | BC9: =IF(RFR_spot_no_VA!BC9="","",RFR_spot_no_VA!BC9) -> 10
B10: =IF(RFR_spot_with_VA!B10="","",RFR_spot_with_VA!B10) -> VA | C10: =IF(RFR_spot_no_VA!C10="","",RFR_spot_no_VA!C10) | J10: =IF(RFR_spot_no_VA!J10="","",RFR_spot_no_VA!J10) | Z10: =IF(RFR_spot_no_VA!Z10="","",RFR_spot_no_VA!Z10) | AH10: =IF(RFR_spot_no_VA!AH10="","",RFR_spot_no_VA!AH10) | AJ10: =IF(RFR_spot_no_VA!AJ10="","",RFR_spot_no_VA!AJ10) | AK10: =IF(RFR_spot_no_VA!AK10="","",RFR_spot_no_VA!AK10) | AM10: =IF(RFR_spot_no_VA!AM10="","",RFR_spot_no_VA!AM10) | AS10: =IF(RFR_spot_no_VA!AS10="","",RFR_spot_no_VA!AS10) | BC10: =IF(RFR_spot_no_VA!BC10="","",RFR_spot_no_VA!BC10)
B11: =RFR_spot_no_VA!B11 -> 1 | C11: =ROUND(IF(RFR_spot_no_VA!C11<0, RFR_spot_no_VA!C11, RFR_spot_no_VA!C11 - Shocks!$D11*ABS(RFR_spot_no_VA!C11 )),5) -> 0.00184 | J11: =ROUND(IF(RFR_spot_no_VA!J11<0, RFR_spot_no_VA!J11, RFR_spot_no_VA!J11 - Shocks!$D11*ABS(RFR_spot_no_VA!J11 )),5) -> 0.00182 | Z11: =ROUND(IF(RFR_spot_no_VA!Z11<0, RFR_spot_no_VA!Z11, RFR_spot_no_VA!Z11 - Shocks!$D11*ABS(RFR_spot_no_VA!Z11 )),5) -> 0.00773 | AH11: =ROUND(IF(RFR_spot_no_VA!AH11<0, RFR_spot_no_VA!AH11, RFR_spot_no_VA!AH11 - Shocks!$D11*ABS(RFR_spot_no_VA!AH11 )),5) -> 0.0059 | AJ11: =ROUND(IF(RFR_spot_no_VA!AJ11<0, RFR_spot_no_VA!AJ11, RFR_spot_no_VA!AJ11 - Shocks!$D11*ABS(RFR_spot_no_VA!AJ11 )),5) -> 0.00623 | AK11: =ROUND(IF(RFR_spot_no_VA!AK11<0, RFR_spot_no_VA!AK11, RFR_spot_no_VA!AK11 - Shocks!$D11*ABS(RFR_spot_no_VA!AK11 )),5) -> 0.00813 | AM11: =ROUND(IF(RFR_spot_no_VA!AM11<0, RFR_spot_no_VA!AM11, RFR_spot_no_VA!AM11 - Shocks!$D11*ABS(RFR_spot_no_VA!AM11 )),5) -> 0.00848 | AS11: =ROUND(IF(RFR_spot_no_VA!AS11<0, RFR_spot_no_VA!AS11, RFR_spot_no_VA!AS11 - Shocks!$D11*ABS(RFR_spot_no_VA!AS11 )),5) -> -0.00108 | BC11: =ROUND(IF(RFR_spot_no_VA!BC11<0, RFR_spot_no_VA!BC11, RFR_spot_no_VA!BC11 - Shocks!$D11*ABS(RFR_spot_no_VA!BC11 )),5) -> 0.00805
B12: =RFR_spot_no_VA!B12 -> 2 | C12: =ROUND(IF(RFR_spot_no_VA!C12<0, RFR_spot_no_VA!C12, RFR_spot_no_VA!C12 - Shocks!$D12*ABS(RFR_spot_no_VA!C12 )),5) -> 0.00443 | J12: =ROUND(IF(RFR_spot_no_VA!J12<0, RFR_spot_no_VA!J12, RFR_spot_no_VA!J12 - Shocks!$D12*ABS(RFR_spot_no_VA!J12 )),5) -> 0.0044 | Z12: =ROUND(IF(RFR_spot_no_VA!Z12<0, RFR_spot_no_VA!Z12, RFR_spot_no_VA!Z12 - Shocks!$D12*ABS(RFR_spot_no_VA!Z12 )),5) -> 0.01087 | AH12: =ROUND(IF(RFR_spot_no_VA!AH12<0, RFR_spot_no_VA!AH12, RFR_spot_no_VA!AH12 - Shocks!$D12*ABS(RFR_spot_no_VA!AH12 )),5) -> 0.00847 | AJ12: =ROUND(IF(RFR_spot_no_VA!AJ12<0, RFR_spot_no_VA!AJ12, RFR_spot_no_VA!AJ12 - Shocks!$D12*ABS(RFR_spot_no_VA!AJ12 )),5) -> 0.00932 | AK12: =ROUND(IF(RFR_spot_no_VA!AK12<0, RFR_spot_no_VA!AK12, RFR_spot_no_VA!AK12 - Shocks!$D12*ABS(RFR_spot_no_VA!AK12 )),5) -> 0.01273 | AM12: =ROUND(IF(RFR_spot_no_VA!AM12<0, RFR_spot_no_VA!AM12, RFR_spot_no_VA!AM12 - Shocks!$D12*ABS(RFR_spot_no_VA!AM12 )),5) -> 0.01189 | AS12: =ROUND(IF(RFR_spot_no_VA!AS12<0, RFR_spot_no_VA!AS12, RFR_spot_no_VA!AS12 - Shocks!$D12*ABS(RFR_spot_no_VA!AS12 )),5) -> -0.00082 | BC12: =ROUND(IF(RFR_spot_no_VA!BC12<0, RFR_spot_no_VA!BC12, RFR_spot_no_VA!BC12 - Shocks!$D12*ABS(RFR_spot_no_VA!BC12 )),5) -> 0.01123
B13: =RFR_spot_no_VA!B13 -> 3 | C13: =ROUND(IF(RFR_spot_no_VA!C13<0, RFR_spot_no_VA!C13, RFR_spot_no_VA!C13 - Shocks!$D13*ABS(RFR_spot_no_VA!C13 )),5) -> 0.00638 | J13: =ROUND(IF(RFR_spot_no_VA!J13<0, RFR_spot_no_VA!J13, RFR_spot_no_VA!J13 - Shocks!$D13*ABS(RFR_spot_no_VA!J13 )),5) -> 0.00633 | Z13: =ROUND(IF(RFR_spot_no_VA!Z13<0, RFR_spot_no_VA!Z13, RFR_spot_no_VA!Z13 - Shocks!$D13*ABS(RFR_spot_no_VA!Z13 )),5) -> 0.01375 | AH13: =ROUND(IF(RFR_spot_no_VA!AH13<0, RFR_spot_no_VA!AH13, RFR_spot_no_VA!AH13 - Shocks!$D13*ABS(RFR_spot_no_VA!AH13 )),5) -> 0.01102 | AJ13: =ROUND(IF(RFR_spot_no_VA!AJ13<0, RFR_spot_no_VA!AJ13, RFR_spot_no_VA!AJ13 - Shocks!$D13*ABS(RFR_spot_no_VA!AJ13 )),5) -> 0.01155 | AK13: =ROUND(IF(RFR_spot_no_VA!AK13<0, RFR_spot_no_VA!AK13, RFR_spot_no_VA!AK13 - Shocks!$D13*ABS(RFR_spot_no_VA!AK13 )),5) -> 0.01653 | AM13: =ROUND(IF(RFR_spot_no_VA!AM13<0, RFR_spot_no_VA!AM13, RFR_spot_no_VA!AM13 - Shocks!$D13*ABS(RFR_spot_no_VA!AM13 )),5) -> 0.01493 | AS13: =ROUND(IF(RFR_spot_no_VA!AS13<0, RFR_spot_no_VA!AS13, RFR_spot_no_VA!AS13 - Shocks!$D13*ABS(RFR_spot_no_VA!AS13 )),5) -> -0.00064 | BC13: =ROUND(IF(RFR_spot_no_VA!BC13<0, RFR_spot_no_VA!BC13, RFR_spot_no_VA!BC13 - Shocks!$D13*ABS(RFR_spot_no_VA!BC13 )),5) -> 0.01346
B14: =RFR_spot_no_VA!B14 -> 4 | C14: =ROUND(IF(RFR_spot_no_VA!C14<0, RFR_spot_no_VA!C14, RFR_spot_no_VA!C14 - Shocks!$D14*ABS(RFR_spot_no_VA!C14 )),5) -> 0.00805 | J14: =ROUND(IF(RFR_spot_no_VA!J14<0, RFR_spot_no_VA!J14, RFR_spot_no_VA!J14 - Shocks!$D14*ABS(RFR_spot_no_VA!J14 )),5) -> 0.008 | Z14: =ROUND(IF(RFR_spot_no_VA!Z14<0, RFR_spot_no_VA!Z14, RFR_spot_no_VA!Z14 - Shocks!$D14*ABS(RFR_spot_no_VA!Z14 )),5) -> 0.01572 | AH14: =ROUND(IF(RFR_spot_no_VA!AH14<0, RFR_spot_no_VA!AH14, RFR_spot_no_VA!AH14 - Shocks!$D14*ABS(RFR_spot_no_VA!AH14 )),5) -> 0.01287 | AJ14: =ROUND(IF(RFR_spot_no_VA!AJ14<0, RFR_spot_no_VA!AJ14, RFR_spot_no_VA!AJ14 - Shocks!$D14*ABS(RFR_spot_no_VA!AJ14 )),5) -> 0.01282 | AK14: =ROUND(IF(RFR_spot_no_VA!AK14<0, RFR_spot_no_VA!AK14, RFR_spot_no_VA!AK14 - Shocks!$D14*ABS(RFR_spot_no_VA!AK14 )),5) -> 0.0192 | AM14: =ROUND(IF(RFR_spot_no_VA!AM14<0, RFR_spot_no_VA!AM14, RFR_spot_no_VA!AM14 - Shocks!$D14*ABS(RFR_spot_no_VA!AM14 )),5) -> 0.0168 | AS14: =ROUND(IF(RFR_spot_no_VA!AS14<0, RFR_spot_no_VA!AS14, RFR_spot_no_VA!AS14 - Shocks!$D14*ABS(RFR_spot_no_VA!AS14 )),5) -> -0.00025 | BC14: =ROUND(IF(RFR_spot_no_VA!BC14<0, RFR_spot_no_VA!BC14, RFR_spot_no_VA!BC14 - Shocks!$D14*ABS(RFR_spot_no_VA!BC14 )),5) -> 0.01508
B15: =RFR_spot_no_VA!B15 -> 5 | C15: =ROUND(IF(RFR_spot_no_VA!C15<0, RFR_spot_no_VA!C15, RFR_spot_no_VA!C15 - Shocks!$D15*ABS(RFR_spot_no_VA!C15 )),5) -> 0.00911 | J15: =ROUND(IF(RFR_spot_no_VA!J15<0, RFR_spot_no_VA!J15, RFR_spot_no_VA!J15 - Shocks!$D15*ABS(RFR_spot_no_VA!J15 )),5) -> 0.00906 | Z15: =ROUND(IF(RFR_spot_no_VA!Z15<0, RFR_spot_no_VA!Z15, RFR_spot_no_VA!Z15 - Shocks!$D15*ABS(RFR_spot_no_VA!Z15 )),5) -> 0.01705 | AH15: =ROUND(IF(RFR_spot_no_VA!AH15<0, RFR_spot_no_VA!AH15, RFR_spot_no_VA!AH15 - Shocks!$D15*ABS(RFR_spot_no_VA!AH15 )),5) -> 0.01414 | AJ15: =ROUND(IF(RFR_spot_no_VA!AJ15<0, RFR_spot_no_VA!AJ15, RFR_spot_no_VA!AJ15 - Shocks!$D15*ABS(RFR_spot_no_VA!AJ15 )),5) -> 0.0136 | AK15: =ROUND(IF(RFR_spot_no_VA!AK15<0, RFR_spot_no_VA!AK15, RFR_spot_no_VA!AK15 - Shocks!$D15*ABS(RFR_spot_no_VA!AK15 )),5) -> 0.02042 | AM15: =ROUND(IF(RFR_spot_no_VA!AM15<0, RFR_spot_no_VA!AM15, RFR_spot_no_VA!AM15 - Shocks!$D15*ABS(RFR_spot_no_VA!AM15 )),5) -> 0.01808 | AS15: =ROUND(IF(RFR_spot_no_VA!AS15<0, RFR_spot_no_VA!AS15, RFR_spot_no_VA!AS15 - Shocks!$D15*ABS(RFR_spot_no_VA!AS15 )),5) -> 0.00019 | BC15: =ROUND(IF(RFR_spot_no_VA!BC15<0, RFR_spot_no_VA!BC15, RFR_spot_no_VA!BC15 - Shocks!$D15*ABS(RFR_spot_no_VA!BC15 )),5) -> 0.01611
B16: =RFR_spot_no_VA!B16 -> 6 | C16: =ROUND(IF(RFR_spot_no_VA!C16<0, RFR_spot_no_VA!C16, RFR_spot_no_VA!C16 - Shocks!$D16*ABS(RFR_spot_no_VA!C16 )),5) -> 0.01034 | J16: =ROUND(IF(RFR_spot_no_VA!J16<0, RFR_spot_no_VA!J16, RFR_spot_no_VA!J16 - Shocks!$D16*ABS(RFR_spot_no_VA!J16 )),5) -> 0.01027 | Z16: =ROUND(IF(RFR_spot_no_VA!Z16<0, RFR_spot_no_VA!Z16, RFR_spot_no_VA!Z16 - Shocks!$D16*ABS(RFR_spot_no_VA!Z16 )),5) -> 0.01835 | AH16: =ROUND(IF(RFR_spot_no_VA!AH16<0, RFR_spot_no_VA!AH16, RFR_spot_no_VA!AH16 - Shocks!$D16*ABS(RFR_spot_no_VA!AH16 )),5) -> 0.01531 | AJ16: =ROUND(IF(RFR_spot_no_VA!AJ16<0, RFR_spot_no_VA!AJ16, RFR_spot_no_VA!AJ16 - Shocks!$D16*ABS(RFR_spot_no_VA!AJ16 )),5) -> 0.01427 | AK16: =ROUND(IF(RFR_spot_no_VA!AK16<0, RFR_spot_no_VA!AK16, RFR_spot_no_VA!AK16 - Shocks!$D16*ABS(RFR_spot_no_VA!AK16 )),5) -> 0.02269 | AM16: =ROUND(IF(RFR_spot_no_VA!AM16<0, RFR_spot_no_VA!AM16, RFR_spot_no_VA!AM16 - Shocks!$D16*ABS(RFR_spot_no_VA!AM16 )),5) -> 0.0196 | AS16: =ROUND(IF(RFR_spot_no_VA!AS16<0, RFR_spot_no_VA!AS16, RFR_spot_no_VA!AS16 - Shocks!$D16*ABS(RFR_spot_no_VA!AS16 )),5) -> 0.00061 | BC16: =ROUND(IF(RFR_spot_no_VA!BC16<0, RFR_spot_no_VA!BC16, RFR_spot_no_VA!BC16 - Shocks!$D16*ABS(RFR_spot_no_VA!BC16 )),5) -> 0.01731
B17: =RFR_spot_no_VA!B17 -> 7 | C17: =ROUND(IF(RFR_spot_no_VA!C17<0, RFR_spot_no_VA!C17, RFR_spot_no_VA!C17 - Shocks!$D17*ABS(RFR_spot_no_VA!C17 )),5) -> 0.01136 | J17: =ROUND(IF(RFR_spot_no_VA!J17<0, RFR_spot_no_VA!J17, RFR_spot_no_VA!J17 - Shocks!$D17*ABS(RFR_spot_no_VA!J17 )),5) -> 0.0113 | Z17: =ROUND(IF(RFR_spot_no_VA!Z17<0, RFR_spot_no_VA!Z17, RFR_spot_no_VA!Z17 - Shocks!$D17*ABS(RFR_spot_no_VA!Z17 )),5) -> 0.01932 | AH17: =ROUND(IF(RFR_spot_no_VA!AH17<0, RFR_spot_no_VA!AH17, RFR_spot_no_VA!AH17 - Shocks!$D17*ABS(RFR_spot_no_VA!AH17 )),5) -> 0.01617 | AJ17: =ROUND(IF(RFR_spot_no_VA!AJ17<0, RFR_spot_no_VA!AJ17, RFR_spot_no_VA!AJ17 - Shocks!$D17*ABS(RFR_spot_no_VA!AJ17 )),5) -> 0.01473 | AK17: =ROUND(IF(RFR_spot_no_VA!AK17<0, RFR_spot_no_VA!AK17, RFR_spot_no_VA!AK17 - Shocks!$D17*ABS(RFR_spot_no_VA!AK17 )),5) -> 0.02477 | AM17: =ROUND(IF(RFR_spot_no_VA!AM17<0, RFR_spot_no_VA!AM17, RFR_spot_no_VA!AM17 - Shocks!$D17*ABS(RFR_spot_no_VA!AM17 )),5) -> 0.02092 | AS17: =ROUND(IF(RFR_spot_no_VA!AS17<0, RFR_spot_no_VA!AS17, RFR_spot_no_VA!AS17 - Shocks!$D17*ABS(RFR_spot_no_VA!AS17 )),5) -> 0.00102 | BC17: =ROUND(IF(RFR_spot_no_VA!BC17<0, RFR_spot_no_VA!BC17, RFR_spot_no_VA!BC17 - Shocks!$D17*ABS(RFR_spot_no_VA!BC17 )),5) -> 0.0182
B18: =RFR_spot_no_VA!B18 -> 8 | C18: =ROUND(IF(RFR_spot_no_VA!C18<0, RFR_spot_no_VA!C18, RFR_spot_no_VA!C18 - Shocks!$D18*ABS(RFR_spot_no_VA!C18 )),5) -> 0.01243 | J18: =ROUND(IF(RFR_spot_no_VA!J18<0, RFR_spot_no_VA!J18, RFR_spot_no_VA!J18 - Shocks!$D18*ABS(RFR_spot_no_VA!J18 )),5) -> 0.01236 | Z18: =ROUND(IF(RFR_spot_no_VA!Z18<0, RFR_spot_no_VA!Z18, RFR_spot_no_VA!Z18 - Shocks!$D18*ABS(RFR_spot_no_VA!Z18 )),5) -> 0.02029 | AH18: =ROUND(IF(RFR_spot_no_VA!AH18<0, RFR_spot_no_VA!AH18, RFR_spot_no_VA!AH18 - Shocks!$D18*ABS(RFR_spot_no_VA!AH18 )),5) -> 0.01702 | AJ18: =ROUND(IF(RFR_spot_no_VA!AJ18<0, RFR_spot_no_VA!AJ18, RFR_spot_no_VA!AJ18 - Shocks!$D18*ABS(RFR_spot_no_VA!AJ18 )),5) -> 0.01526 | AK18: =ROUND(IF(RFR_spot_no_VA!AK18<0, RFR_spot_no_VA!AK18, RFR_spot_no_VA!AK18 - Shocks!$D18*ABS(RFR_spot_no_VA!AK18 )),5) -> 0.02628 | AM18: =ROUND(IF(RFR_spot_no_VA!AM18<0, RFR_spot_no_VA!AM18, RFR_spot_no_VA!AM18 - Shocks!$D18*ABS(RFR_spot_no_VA!AM18 )),5) -> 0.02228 | AS18: =ROUND(IF(RFR_spot_no_VA!AS18<0, RFR_spot_no_VA!AS18, RFR_spot_no_VA!AS18 - Shocks!$D18*ABS(RFR_spot_no_VA!AS18 )),5) -> 0.00143 | BC18: =ROUND(IF(RFR_spot_no_VA!BC18<0, RFR_spot_no_VA!BC18, RFR_spot_no_VA!BC18 - Shocks!$D18*ABS(RFR_spot_no_VA!BC18 )),5) -> 0.01909
B19: =RFR_spot_no_VA!B19 -> 9 | C19: =ROUND(IF(RFR_spot_no_VA!C19<0, RFR_spot_no_VA!C19, RFR_spot_no_VA!C19 - Shocks!$D19*ABS(RFR_spot_no_VA!C19 )),5) -> 0.01351 | J19: =ROUND(IF(RFR_spot_no_VA!J19<0, RFR_spot_no_VA!J19, RFR_spot_no_VA!J19 - Shocks!$D19*ABS(RFR_spot_no_VA!J19 )),5) -> 0.01345 | Z19: =ROUND(IF(RFR_spot_no_VA!Z19<0, RFR_spot_no_VA!Z19, RFR_spot_no_VA!Z19 - Shocks!$D19*ABS(RFR_spot_no_VA!Z19 )),5) -> 0.02127 | AH19: =ROUND(IF(RFR_spot_no_VA!AH19<0, RFR_spot_no_VA!AH19, RFR_spot_no_VA!AH19 - Shocks!$D19*ABS(RFR_spot_no_VA!AH19 )),5) -> 0.01793 | AJ19: =ROUND(IF(RFR_spot_no_VA!AJ19<0, RFR_spot_no_VA!AJ19, RFR_spot_no_VA!AJ19 - Shocks!$D19*ABS(RFR_spot_no_VA!AJ19 )),5) -> 0.01585 | AK19: =ROUND(IF(RFR_spot_no_VA!AK19<0, RFR_spot_no_VA!AK19, RFR_spot_no_VA!AK19 - Shocks!$D19*ABS(RFR_spot_no_VA!AK19 )),5) -> 0.02773 | AM19: =ROUND(IF(RFR_spot_no_VA!AM19<0, RFR_spot_no_VA!AM19, RFR_spot_no_VA!AM19 - Shocks!$D19*ABS(RFR_spot_no_VA!AM19 )),5) -> 0.02362 | AS19: =ROUND(IF(RFR_spot_no_VA!AS19<0, RFR_spot_no_VA!AS19, RFR_spot_no_VA!AS19 - Shocks!$D19*ABS(RFR_spot_no_VA!AS19 )),5) -> 0.00184 | BC19: =ROUND(IF(RFR_spot_no_VA!BC19<0, RFR_spot_no_VA!BC19, RFR_spot_no_VA!BC19 - Shocks!$D19*ABS(RFR_spot_no_VA!BC19 )),5) -> 0.02005
B20: =RFR_spot_no_VA!B20 -> 10 | C20: =ROUND(IF(RFR_spot_no_VA!C20<0, RFR_spot_no_VA!C20, RFR_spot_no_VA!C20 - Shocks!$D20*ABS(RFR_spot_no_VA!C20 )),5) -> 0.01441 | J20: =ROUND(IF(RFR_spot_no_VA!J20<0, RFR_spot_no_VA!J20, RFR_spot_no_VA!J20 - Shocks!$D20*ABS(RFR_spot_no_VA!J20 )),5) -> 0.01435 | Z20: =ROUND(IF(RFR_spot_no_VA!Z20<0, RFR_spot_no_VA!Z20, RFR_spot_no_VA!Z20 - Shocks!$D20*ABS(RFR_spot_no_VA!Z20 )),5) -> 0.02193 | AH20: =ROUND(IF(RFR_spot_no_VA!AH20<0, RFR_spot_no_VA!AH20, RFR_spot_no_VA!AH20 - Shocks!$D20*ABS(RFR_spot_no_VA!AH20 )),5) -> 0.01863 | AJ20: =ROUND(IF(RFR_spot_no_VA!AJ20<0, RFR_spot_no_VA!AJ20, RFR_spot_no_VA!AJ20 - Shocks!$D20*ABS(RFR_spot_no_VA!AJ20 )),5) -> 0.01628 | AK20: =ROUND(IF(RFR_spot_no_VA!AK20<0, RFR_spot_no_VA!AK20, RFR_spot_no_VA!AK20 - Shocks!$D20*ABS(RFR_spot_no_VA!AK20 )),5) -> 0.02806 | AM20: =ROUND(IF(RFR_spot_no_VA!AM20<0, RFR_spot_no_VA!AM20, RFR_spot_no_VA!AM20 - Shocks!$D20*ABS(RFR_spot_no_VA!AM20 )),5) -> 0.02455 | AS20: =ROUND(IF(RFR_spot_no_VA!AS20<0, RFR_spot_no_VA!AS20, RFR_spot_no_VA!AS20 - Shocks!$D20*ABS(RFR_spot_no_VA!AS20 )),5) -> 0.00229 | BC20: =ROUND(IF(RFR_spot_no_VA!BC20<0, RFR_spot_no_VA!BC20, RFR_spot_no_VA!BC20 - Shocks!$D20*ABS(RFR_spot_no_VA!BC20 )),5) -> 0.0208
B21: =RFR_spot_no_VA!B21 -> 11 | C21: =ROUND(IF(RFR_spot_no_VA!C21<0, RFR_spot_no_VA!C21, RFR_spot_no_VA!C21 - Shocks!$D21*ABS(RFR_spot_no_VA!C21 )),5) -> 0.01525 | J21: =ROUND(IF(RFR_spot_no_VA!J21<0, RFR_spot_no_VA!J21, RFR_spot_no_VA!J21 - Shocks!$D21*ABS(RFR_spot_no_VA!J21 )),5) -> 0.01518 | Z21: =ROUND(IF(RFR_spot_no_VA!Z21<0, RFR_spot_no_VA!Z21, RFR_spot_no_VA!Z21 - Shocks!$D21*ABS(RFR_spot_no_VA!Z21 )),5) -> 0.02227 | AH21: =ROUND(IF(RFR_spot_no_VA!AH21<0, RFR_spot_no_VA!AH21, RFR_spot_no_VA!AH21 - Shocks!$D21*ABS(RFR_spot_no_VA!AH21 )),5) -> 0.01913 | AJ21: =ROUND(IF(RFR_spot_no_VA!AJ21<0, RFR_spot_no_VA!AJ21, RFR_spot_no_VA!AJ21 - Shocks!$D21*ABS(RFR_spot_no_VA!AJ21 )),5) -> 0.0165 | AK21: =ROUND(IF(RFR_spot_no_VA!AK21<0, RFR_spot_no_VA!AK21, RFR_spot_no_VA!AK21 - Shocks!$D21*ABS(RFR_spot_no_VA!AK21 )),5) -> 0.02846 | AM21: =ROUND(IF(RFR_spot_no_VA!AM21<0, RFR_spot_no_VA!AM21, RFR_spot_no_VA!AM21 - Shocks!$D21*ABS(RFR_spot_no_VA!AM21 )),5) -> 0.02503 | AS21: =ROUND(IF(RFR_spot_no_VA!AS21<0, RFR_spot_no_VA!AS21, RFR_spot_no_VA!AS21 - Shocks!$D21*ABS(RFR_spot_no_VA!AS21 )),5) -> 0.00277 | BC21: =ROUND(IF(RFR_spot_no_VA!BC21<0, RFR_spot_no_VA!BC21, RFR_spot_no_VA!BC21 - Shocks!$D21*ABS(RFR_spot_no_VA!BC21 )),5) -> 0.02123
B22: =RFR_spot_no_VA!B22 -> 12 | C22: =ROUND(IF(RFR_spot_no_VA!C22<0, RFR_spot_no_VA!C22, RFR_spot_no_VA!C22 - Shocks!$D22*ABS(RFR_spot_no_VA!C22 )),5) -> 0.01567 | J22: =ROUND(IF(RFR_spot_no_VA!J22<0, RFR_spot_no_VA!J22, RFR_spot_no_VA!J22 - Shocks!$D22*ABS(RFR_spot_no_VA!J22 )),5) -> 0.0156 | Z22: =ROUND(IF(RFR_spot_no_VA!Z22<0, RFR_spot_no_VA!Z22, RFR_spot_no_VA!Z22 - Shocks!$D22*ABS(RFR_spot_no_VA!Z22 )),5) -> 0.02262 | AH22: =ROUND(IF(RFR_spot_no_VA!AH22<0, RFR_spot_no_VA!AH22, RFR_spot_no_VA!AH22 - Shocks!$D22*ABS(RFR_spot_no_VA!AH22 )),5) -> 0.01967 | AJ22: =ROUND(IF(RFR_spot_no_VA!AJ22<0, RFR_spot_no_VA!AJ22, RFR_spot_no_VA!AJ22 - Shocks!$D22*ABS(RFR_spot_no_VA!AJ22 )),5) -> 0.0167 | AK22: =ROUND(IF(RFR_spot_no_VA!AK22<0, RFR_spot_no_VA!AK22, RFR_spot_no_VA!AK22 - Shocks!$D22*ABS(RFR_spot_no_VA!AK22 )),5) -> 0.02912 | AM22: =ROUND(IF(RFR_spot_no_VA!AM22<0, RFR_spot_no_VA!AM22, RFR_spot_no_VA!AM22 - Shocks!$D22*ABS(RFR_spot_no_VA!AM22 )),5) -> 0.02543 | AS22: =ROUND(IF(RFR_spot_no_VA!AS22<0, RFR_spot_no_VA!AS22, RFR_spot_no_VA!AS22 - Shocks!$D22*ABS(RFR_spot_no_VA!AS22 )),5) -> 0.0033 | BC22: =ROUND(IF(RFR_spot_no_VA!BC22<0, RFR_spot_no_VA!BC22, RFR_spot_no_VA!BC22 - Shocks!$D22*ABS(RFR_spot_no_VA!BC22 )),5) -> 0.02167
... B160: =RFR_spot_no_VA!B160 -> 150 | C160: =ROUND(IF(RFR_spot_no_VA!C160<0, RFR_spot_no_VA!C160, RFR_spot_no_VA!C160 - Shocks!$D160*ABS(RFR_spot_no_VA!C160 )),5) -> 0.02558 | J160: =ROUND(IF(RFR_spot_no_VA!J160<0, RFR_spot_no_VA!J160, RFR_spot_no_VA!J160 - Shocks!$D160*ABS(RFR_spot_no_VA!J160 )),5) -> 0.02557 | Z160: =ROUND(IF(RFR_spot_no_VA!Z160<0, RFR_spot_no_VA!Z160, RFR_spot_no_VA!Z160 - Shocks!$D160*ABS(RFR_spot_no_VA!Z160 )),5) -> 0.02726 | AH160: =ROUND(IF(RFR_spot_no_VA!AH160<0, RFR_spot_no_VA!AH160, RFR_spot_no_VA!AH160 - Shocks!$D160*ABS(RFR_spot_no_VA!AH160 )),5) -> 0.02714 | AJ160: =ROUND(IF(RFR_spot_no_VA!AJ160<0, RFR_spot_no_VA!AJ160, RFR_spot_no_VA!AJ160 - Shocks!$D160*ABS(RFR_spot_no_VA!AJ160 )),5) -> 0.0229 | AK160: =ROUND(IF(RFR_spot_no_VA!AK160<0, RFR_spot_no_VA!AK160, RFR_spot_no_VA!AK160 - Shocks!$D160*ABS(RFR_spot_no_VA!AK160 )),5) -> 0.02725 | AM160: =ROUND(IF(RFR_spot_no_VA!AM160<0, RFR_spot_no_VA!AM160, RFR_spot_no_VA!AM160 - Shocks!$D160*ABS(RFR_spot_no_VA!AM160 )),5) -> 0.0273 | AS160: =ROUND(IF(RFR_spot_no_VA!AS160<0, RFR_spot_no_VA!AS160, RFR_spot_no_VA!AS160 - Shocks!$D160*ABS(RFR_spot_no_VA!AS160 )),5) -> 0.02386 | BC160: =ROUND(IF(RFR_spot_no_VA!BC160<0, RFR_spot_no_VA!BC160, RFR_spot_no_VA!BC160 - Shocks!$D160*ABS(RFR_spot_no_VA!BC160 )),5) -> 0.02604

Sheet Spot_WITH_VA_shock_UP
B2: Main menu | C2: =IF(RFR_spot_no_VA!C2="","",RFR_spot_no_VA!C2) -> Euro | D2: =IF(RFR_spot_no_VA!D2="","",RFR_spot_no_VA!D2) | E2: =IF(RFR_spot_no_VA!E2="","",RFR_spot_no_VA!E2) | F2: =IF(RFR_spot_no_VA!F2="","",RFR_spot_no_VA!F2) | G2: =IF(RFR_spot_no_VA!G2="","",RFR_spot_no_VA!G2) | H2: =IF(RFR_spot_no_VA!H2="","",RFR_spot_no_VA!H2) | I2: =IF(RFR_spot_no_VA!I2="","",RFR_spot_no_VA!I2) | J2: =IF(RFR_spot_no_VA!J2="","",RFR_spot_no_VA!J2) -> Denmark | ... BC2: =IF(RFR_spot_no_VA!BC2="","",RFR_spot_no_VA!BC2) -> United States
B3: =IF(RFR_spot_with_VA!B3="","",RFR_spot_with_VA!B3) | C3: =IF(RFR_spot_no_VA!C3="","",RFR_spot_no_VA!C3) -> EUR_30_6_2022_SWP_LLP_20_EXT_40_UFR_3.45 | J3: =IF(RFR_spot_no_VA!J3="","",RFR_spot_no_VA!J3) -> DK_30_6_2022_SWP_LLP_20_EXT_40_UFR_3.45 | Z3: =IF(RFR_spot_no_VA!Z3="","",RFR_spot_no_VA!Z3) -> NO_30_6_2022_SWP_LLP_10_EXT_50_UFR_3.45 | AH3: =IF(RFR_spot_no_VA!AH3="","",RFR_spot_no_VA!AH3) -> SE_30_6_2022_SWP_LLP_10_EXT_10_UFR_3.45 | AJ3: =IF(RFR_spot_no_VA!AJ3="","",RFR_spot_no_VA!AJ3) -> GB_30_6_2022_SWP_LLP_50_EXT_40_UFR_3.45 | AK3: =IF(RFR_spot_no_VA!AK3="","",RFR_spot_no_VA!AK3) -> AU_30_6_2022_SWP_LLP_30_EXT_40_UFR_3.45 | AM3: =IF(RFR_spot_no_VA!AM3="","",RFR_spot_no_VA!AM3) -> CA_30_6_2022_SWP_LLP_30_EXT_40_UFR_3.45 | AS3: =IF(RFR_spot_no_VA!AS3="","",RFR_spot_no_VA!AS3) -> JP_30_6_2022_GVT_LLP_30_EXT_40_UFR_3.5 | BC3: =IF(RFR_spot_no_VA!BC3="","",RFR_spot_no_VA!BC3) -> US_30_6_2022_SWP_LLP_30_EXT_40_UFR_3.45
B4: =IF(RFR_spot_with_VA!B4="","",RFR_spot_with_VA!B4) -> Coupon_freq | C4: =IF(RFR_spot_no_VA!C4="","",RFR_spot_no_VA!C4) -> 1 | J4: =IF(RFR_spot_no_VA!J4="","",RFR_spot_no_VA!J4) -> 1 | Z4: =IF(RFR_spot_no_VA!Z4="","",RFR_spot_no_VA!Z4) -> 1 | AH4: =IF(RFR_spot_no_VA!AH4="","",RFR_spot_no_VA!AH4) -> 1 | AJ4: =IF(RFR_spot_no_VA!AJ4="","",RFR_spot_no_VA!AJ4) -> 1 | AK4: =IF(RFR_spot_no_VA!AK4="","",RFR_spot_no_VA!AK4) -> 2 | AM4: =IF(RFR_spot_no_VA!AM4="","",RFR_spot_no_VA!AM4) -> 2 | AS4: =IF(RFR_spot_no_VA!AS4="","",RFR_spot_no_VA!AS4) -> 0 | BC4: =IF(RFR_spot_no_VA!BC4="","",RFR_spot_no_VA!BC4) -> 2
B5: =IF(RFR_spot_with_VA!B5="","",RFR_spot_with_VA!B5) -> LLP | C5: =IF(RFR_spot_no_VA!C5="","",RFR_spot_no_VA!C5) -> 20 | J5: =IF(RFR_spot_no_VA!J5="","",RFR_spot_no_VA!J5) -> 20 | Z5: =IF(RFR_spot_no_VA!Z5="","",RFR_spot_no_VA!Z5) -> 10 | AH5: =IF(RFR_spot_no_VA!AH5="","",RFR_spot_no_VA!AH5) -> 10 | AJ5: =IF(RFR_spot_no_VA!AJ5="","",RFR_spot_no_VA!AJ5) -> 50 | AK5: =IF(RFR_spot_no_VA!AK5="","",RFR_spot_no_VA!AK5) -> 30 | AM5: =IF(RFR_spot_no_VA!AM5="","",RFR_spot_no_VA!AM5) -> 30 | AS5: =IF(RFR_spot_no_VA!AS5="","",RFR_spot_no_VA!AS5) -> 30 | BC5: =IF(RFR_spot_no_VA!BC5="","",RFR_spot_no_VA!BC5) -> 30
B6: =IF(RFR_spot_with_VA!B6="","",RFR_spot_with_VA!B6) -> Convergence | C6: =IF(RFR_spot_no_VA!C6="","",RFR_spot_no_VA!C6) -> 40 | J6: =IF(RFR_spot_no_VA!J6="","",RFR_spot_no_VA!J6) -> 40 | Z6: =IF(RFR_spot_no_VA!Z6="","",RFR_spot_no_VA!Z6) -> 50 | AH6: =IF(RFR_spot_no_VA!AH6="","",RFR_spot_no_VA!AH6) -> 10 | AJ6: =IF(RFR_spot_no_VA!AJ6="","",RFR_spot_no_VA!AJ6) -> 40 | AK6: =IF(RFR_spot_no_VA!AK6="","",RFR_spot_no_VA!AK6) -> 40 | AM6: =IF(RFR_spot_no_VA!AM6="","",RFR_spot_no_VA!AM6) -> 40 | AS6: =IF(RFR_spot_no_VA!AS6="","",RFR_spot_no_VA!AS6) -> 40 | BC6: =IF(RFR_spot_no_VA!BC6="","",RFR_spot_no_VA!BC6) -> 40
B7: =IF(RFR_spot_with_VA!B7="","",RFR_spot_with_VA!B7) -> UFR | C7: =IF(RFR_spot_no_VA!C7="","",RFR_spot_no_VA!C7) -> 3.45 | J7: =IF(RFR_spot_no_VA!J7="","",RFR_spot_no_VA!J7) -> 3.45 | Z7: =IF(RFR_spot_no_VA!Z7="","",RFR_spot_no_VA!Z7) -> 3.45 | AH7: =IF(RFR_spot_no_VA!AH7="","",RFR_spot_no_VA!AH7) -> 3.45 | AJ7: =IF(RFR_spot_no_VA!AJ7="","",RFR_spot_no_VA!AJ7) -> 3.45 | AK7: =IF(RFR_spot_no_VA!AK7="","",RFR_spot_no_VA!AK7) -> 3.45 | AM7: =IF(RFR_spot_no_VA!AM7="","",RFR_spot_no_VA!AM7) -> 3.45 | AS7: =IF(RFR_spot_no_VA!AS7="","",RFR_spot_no_VA!AS7) -> 3.5 | BC7: =IF(RFR_spot_no_VA!BC7="","",RFR_spot_no_VA!BC7) -> 3.45
B9: =IF(RFR_spot_with_VA!B9="","",RFR_spot_with_VA!B9) -> CRA | C9: =IF(RFR_spot_no_VA!C9="","",RFR_spot_no_VA!C9) -> 10 | J9: =IF(RFR_spot_no_VA!J9="","",RFR_spot_no_VA!J9) -> 11 | Z9: =IF(RFR_spot_no_VA!Z9="","",RFR_spot_no_VA!Z9) -> 10 | AH9: =IF(RFR_spot_no_VA!AH9="","",RFR_spot_no_VA!AH9) -> 10 | AJ9: =IF(RFR_spot_no_VA!AJ9="","",RFR_spot_no_VA!AJ9) -> 0 | AK9: =IF(RFR_spot_no_VA!AK9="","",RFR_spot_no_VA!AK9) -> 10 | AM9: =IF(RFR_spot_no_VA!AM9="","",RFR_spot_no_VA!AM9) -> 16 | AS9: =IF(RFR_spot_no_VA!AS9="","",RFR_spot_no_VA!AS9) -> 0 | BC9: =IF(RFR_spot_no_VA!BC9="","",RFR_spot_no_VA!BC9) -> 10
B10: =IF(RFR_spot_with_VA!B10="","",RFR_spot_with_VA!B10) -> VA | C10: =IF(RFR_spot_with_VA!C10="","",RFR_spot_with_VA!C10) -> 25 | J10: =IF(RFR_spot_with_VA!J10="","",RFR_spot_with_VA!J10) -> 33 | Z10: =IF(RFR_spot_with_VA!Z10="","",RFR_spot_with_VA!Z10) -> 51 | AH10: =IF(RFR_spot_with_VA!AH10="","",RFR_spot_with_VA!AH10) -> 19 | AJ10: =IF(RFR_spot_with_VA!AJ10="","",RFR_spot_with_VA!AJ10) -> 30 | AK10: =IF(RFR_spot_with_VA!AK10="","",RFR_spot_with_VA!AK10) -> 28 | AM10: =IF(RFR_spot_with_VA!AM10="","",RFR_spot_with_VA!AM10) -> 47 | AS10: =IF(RFR_spot_with_VA!AS10="","",RFR_spot_with_VA!AS10) -> 0 | BC10: =IF(RFR_spot_with_VA!BC10="","",RFR_spot_with_VA!BC10) -> 47
B11: =RFR_spot_no_VA!B11 -> 1 | C11: =ROUND(RFR_spot_no_VA!C11 + MAX(0.01,Shocks!$E11*ABS(RFR_spot_no_VA!C11) )+VA!C11,5) -> 0.01986 | J11: =ROUND(RFR_spot_no_VA!J11 + MAX(0.01,Shocks!$E11*ABS(RFR_spot_no_VA!J11) )+VA!J11,5) -> 0.02056 | Z11: =ROUND(RFR_spot_no_VA!Z11 + MAX(0.01,Shocks!$E11*ABS(RFR_spot_no_VA!Z11) )+VA!Z11,5) -> 0.05766 | AH11: =ROUND(RFR_spot_no_VA!AH11 + MAX(0.01,Shocks!$E11*ABS(RFR_spot_no_VA!AH11) )+VA!AH11,5) -> 0.04204 | AJ11: =ROUND(RFR_spot_no_VA!AJ11 + MAX(0.01,Shocks!$E11*ABS(RFR_spot_no_VA!AJ11) )+VA!AJ11,5) -> 0.04535 | AK11: =ROUND(RFR_spot_no_VA!AK11 + MAX(0.01,Shocks!$E11*ABS(RFR_spot_no_VA!AK11) )+VA!AK11,5) -> 0.05807 | AM11: =ROUND(RFR_spot_no_VA!AM11 + MAX(0.01,Shocks!$E11*ABS(RFR_spot_no_VA!AM11) )+VA!AM11,5) -> 0.06236 | AS11: =ROUND(RFR_spot_no_VA!AS11 + MAX(0.01,Shocks!$E11*ABS(RFR_spot_no_VA!AS11) )+VA!AS11,5) -> 0.00892 | BC11: =ROUND(RFR_spot_no_VA!BC11 + MAX(0.01,Shocks!$E11*ABS(RFR_spot_no_VA!BC11) )+VA!BC11,5) -> 0.05941
B12: =RFR_spot_no_VA!B12 -> 2 | C12: =ROUND(RFR_spot_no_VA!C12 + MAX(0.01,Shocks!$E12*ABS(RFR_spot_no_VA!C12) )+VA!C12,5) -> 0.02516 | J12: =ROUND(RFR_spot_no_VA!J12 + MAX(0.01,Shocks!$E12*ABS(RFR_spot_no_VA!J12) )+VA!J12,5) -> 0.02586 | Z12: =ROUND(RFR_spot_no_VA!Z12 + MAX(0.01,Shocks!$E12*ABS(RFR_spot_no_VA!Z12) )+VA!Z12,5) -> 0.0579 | AH12: =ROUND(RFR_spot_no_VA!AH12 + MAX(0.01,Shocks!$E12*ABS(RFR_spot_no_VA!AH12) )+VA!AH12,5) -> 0.04306 | AJ12: =ROUND(RFR_spot_no_VA!AJ12 + MAX(0.01,Shocks!$E12*ABS(RFR_spot_no_VA!AJ12) )+VA!AJ12,5) -> 0.04827 | AK12: =ROUND(RFR_spot_no_VA!AK12 + MAX(0.01,Shocks!$E12*ABS(RFR_spot_no_VA!AK12) )+VA!AK12,5) -> 0.06465 | AM12: =ROUND(RFR_spot_no_VA!AM12 + MAX(0.01,Shocks!$E12*ABS(RFR_spot_no_VA!AM12) )+VA!AM12,5) -> 0.06245 | AS12: =ROUND(RFR_spot_no_VA!AS12 + MAX(0.01,Shocks!$E12*ABS(RFR_spot_no_VA!AS12) )+VA!AS12,5) -> 0.00918 | BC12: =ROUND(RFR_spot_no_VA!BC12 + MAX(0.01,Shocks!$E12*ABS(RFR_spot_no_VA!BC12) )+VA!BC12,5) -> 0.05924
B13: =RFR_spot_no_VA!B13 -> 3 | C13: =ROUND(RFR_spot_no_VA!C13 + MAX(0.01,Shocks!$E13*ABS(RFR_spot_no_VA!C13) )+VA!C13,5) -> 0.02699 | J13: =ROUND(RFR_spot_no_VA!J13 + MAX(0.01,Shocks!$E13*ABS(RFR_spot_no_VA!J13) )+VA!J13,5) -> 0.02769 | Z13: =ROUND(RFR_spot_no_VA!Z13 + MAX(0.01,Shocks!$E13*ABS(RFR_spot_no_VA!Z13) )+VA!Z13,5) -> 0.05637 | AH13: =ROUND(RFR_spot_no_VA!AH13 + MAX(0.01,Shocks!$E13*ABS(RFR_spot_no_VA!AH13) )+VA!AH13,5) -> 0.04297 | AJ13: =ROUND(RFR_spot_no_VA!AJ13 + MAX(0.01,Shocks!$E13*ABS(RFR_spot_no_VA!AJ13) )+VA!AJ13,5) -> 0.04607 | AK13: =ROUND(RFR_spot_no_VA!AK13 + MAX(0.01,Shocks!$E13*ABS(RFR_spot_no_VA!AK13) )+VA!AK13,5) -> 0.0644 | AM13: =ROUND(RFR_spot_no_VA!AM13 + MAX(0.01,Shocks!$E13*ABS(RFR_spot_no_VA!AM13) )+VA!AM13,5) -> 0.06035 | AS13: =ROUND(RFR_spot_no_VA!AS13 + MAX(0.01,Shocks!$E13*ABS(RFR_spot_no_VA!AS13) )+VA!AS13,5) -> 0.00936 | BC13: =ROUND(RFR_spot_no_VA!BC13 + MAX(0.01,Shocks!$E13*ABS(RFR_spot_no_VA!BC13) )+VA!BC13,5) -> 0.05485
B14: =RFR_spot_no_VA!B14 -> 4 | C14: =ROUND(RFR_spot_no_VA!C14 + MAX(0.01,Shocks!$E14*ABS(RFR_spot_no_VA!C14) )+VA!C14,5) -> 0.0286 | J14: =ROUND(RFR_spot_no_VA!J14 + MAX(0.01,Shocks!$E14*ABS(RFR_spot_no_VA!J14) )+VA!J14,5) -> 0.0293 | Z14: =ROUND(RFR_spot_no_VA!Z14 + MAX(0.01,Shocks!$E14*ABS(RFR_spot_no_VA!Z14) )+VA!Z14,5) -> 0.05509 | AH14: =ROUND(RFR_spot_no_VA!AH14 + MAX(0.01,Shocks!$E14*ABS(RFR_spot_no_VA!AH14) )+VA!AH14,5) -> 0.04283 | AJ14: =ROUND(RFR_spot_no_VA!AJ14 + MAX(0.01,Shocks!$E14*ABS(RFR_spot_no_VA!AJ14) )+VA!AJ14,5) -> 0.04377 | AK14: =ROUND(RFR_spot_no_VA!AK14 + MAX(0.01,Shocks!$E14*ABS(RFR_spot_no_VA!AK14) )+VA!AK14,5) -> 0.06384 | AM14: =ROUND(RFR_spot_no_VA!AM14 + MAX(0.01,Shocks!$E14*ABS(RFR_spot_no_VA!AM14) )+VA!AM14,5) -> 0.05812 | AS14: =ROUND(RFR_spot_no_VA!AS14 + MAX(0.01,Shocks!$E14*ABS(RFR_spot_no_VA!AS14) )+VA!AS14,5) -> 0.00975 | BC14: =ROUND(RFR_spot_no_VA!BC14 + MAX(0.01,Shocks!$E14*ABS(RFR_spot_no_VA!BC14) )+VA!BC14,5) -> 0.05264
B15: =RFR_spot_no_VA!B15 -> 5 | C15: =ROUND(RFR_spot_no_VA!C15 + MAX(0.01,Shocks!$E15*ABS(RFR_spot_no_VA!C15) )+VA!C15,5) -> 0.02937 | J15: =ROUND(RFR_spot_no_VA!J15 + MAX(0.01,Shocks!$E15*ABS(RFR_spot_no_VA!J15) )+VA!J15,5) -> 0.03007 | Z15: =ROUND(RFR_spot_no_VA!Z15 + MAX(0.01,Shocks!$E15*ABS(RFR_spot_no_VA!Z15) )+VA!Z15,5) -> 0.05403 | AH15: =ROUND(RFR_spot_no_VA!AH15 + MAX(0.01,Shocks!$E15*ABS(RFR_spot_no_VA!AH15) )+VA!AH15,5) -> 0.04249 | AJ15: =ROUND(RFR_spot_no_VA!AJ15 + MAX(0.01,Shocks!$E15*ABS(RFR_spot_no_VA!AJ15) )+VA!AJ15,5) -> 0.04203 | AK15: =ROUND(RFR_spot_no_VA!AK15 + MAX(0.01,Shocks!$E15*ABS(RFR_spot_no_VA!AK15) )+VA!AK15,5) -> 0.06141 | AM15: =ROUND(RFR_spot_no_VA!AM15 + MAX(0.01,Shocks!$E15*ABS(RFR_spot_no_VA!AM15) )+VA!AM15,5) -> 0.05661 | AS15: =ROUND(RFR_spot_no_VA!AS15 + MAX(0.01,Shocks!$E15*ABS(RFR_spot_no_VA!AS15) )+VA!AS15,5) -> 0.01036 | BC15: =ROUND(RFR_spot_no_VA!BC15 + MAX(0.01,Shocks!$E15*ABS(RFR_spot_no_VA!BC15) )+VA!BC15,5) -> 0.05095
B16: =RFR_spot_no_VA!B16 -> 6 | C16: =ROUND(RFR_spot_no_VA!C16 + MAX(0.01,Shocks!$E16*ABS(RFR_spot_no_VA!C16) )+VA!C16,5) -> 0.03032 | J16: =ROUND(RFR_spot_no_VA!J16 + MAX(0.01,Shocks!$E16*ABS(RFR_spot_no_VA!J16) )+VA!J16,5) -> 0.03101 | Z16: =ROUND(RFR_spot_no_VA!Z16 + MAX(0.01,Shocks!$E16*ABS(RFR_spot_no_VA!Z16) )+VA!Z16,5) -> 0.05319 | AH16: =ROUND(RFR_spot_no_VA!AH16 + MAX(0.01,Shocks!$E16*ABS(RFR_spot_no_VA!AH16) )+VA!AH16,5) -> 0.04201 | AJ16: =ROUND(RFR_spot_no_VA!AJ16 + MAX(0.01,Shocks!$E16*ABS(RFR_spot_no_VA!AJ16) )+VA!AJ16,5) -> 0.04041 | AK16: =ROUND(RFR_spot_no_VA!AK16 + MAX(0.01,Shocks!$E16*ABS(RFR_spot_no_VA!AK16) )+VA!AK16,5) -> 0.06226 | AM16: =ROUND(RFR_spot_no_VA!AM16 + MAX(0.01,Shocks!$E16*ABS(RFR_spot_no_VA!AM16) )+VA!AM16,5) -> 0.05606 | AS16: =ROUND(RFR_spot_no_VA!AS16 + MAX(0.01,Shocks!$E16*ABS(RFR_spot_no_VA!AS16) )+VA!AS16,5) -> 0.01105 | BC16: =ROUND(RFR_spot_no_VA!BC16 + MAX(0.01,Shocks!$E16*ABS(RFR_spot_no_VA!BC16) )+VA!BC16,5) -> 0.05006
B17: =RFR_spot_no_VA!B17 -> 7 | C17: =ROUND(RFR_spot_no_VA!C17 + MAX(0.01,Shocks!$E17*ABS(RFR_spot_no_VA!C17) )+VA!C17,5) -> 0.03113 | J17: =ROUND(RFR_spot_no_VA!J17 + MAX(0.01,Shocks!$E17*ABS(RFR_spot_no_VA!J17) )+VA!J17,5) -> 0.03183 | Z17: =ROUND(RFR_spot_no_VA!Z17 + MAX(0.01,Shocks!$E17*ABS(RFR_spot_no_VA!Z17) )+VA!Z17,5) -> 0.0523 | AH17: =ROUND(RFR_spot_no_VA!AH17 + MAX(0.01,Shocks!$E17*ABS(RFR_spot_no_VA!AH17) )+VA!AH17,5) -> 0.04139 | AJ17: =ROUND(RFR_spot_no_VA!AJ17 + MAX(0.01,Shocks!$E17*ABS(RFR_spot_no_VA!AJ17) )+VA!AJ17,5) -> 0.03897 | AK17: =ROUND(RFR_spot_no_VA!AK17 + MAX(0.01,Shocks!$E17*ABS(RFR_spot_no_VA!AK17) )+VA!AK17,5) -> 0.06329 | AM17: =ROUND(RFR_spot_no_VA!AM17 + MAX(0.01,Shocks!$E17*ABS(RFR_spot_no_VA!AM17) )+VA!AM17,5) -> 0.05579 | AS17: =ROUND(RFR_spot_no_VA!AS17 + MAX(0.01,Shocks!$E17*ABS(RFR_spot_no_VA!AS17) )+VA!AS17,5) -> 0.01168 | BC17: =ROUND(RFR_spot_no_VA!BC17 + MAX(0.01,Shocks!$E17*ABS(RFR_spot_no_VA!BC17) )+VA!BC17,5) -> 0.04915
B18: =RFR_spot_no_VA!B18 -> 8 | C18: =ROUND(RFR_spot_no_VA!C18 + MAX(0.01,Shocks!$E18*ABS(RFR_spot_no_VA!C18) )+VA!C18,5) -> 0.03192 | J18: =ROUND(RFR_spot_no_VA!J18 + MAX(0.01,Shocks!$E18*ABS(RFR_spot_no_VA!J18) )+VA!J18,5) -> 0.03262 | Z18: =ROUND(RFR_spot_no_VA!Z18 + MAX(0.01,Shocks!$E18*ABS(RFR_spot_no_VA!Z18) )+VA!Z18,5) -> 0.05171 | AH18: =ROUND(RFR_spot_no_VA!AH18 + MAX(0.01,Shocks!$E18*ABS(RFR_spot_no_VA!AH18) )+VA!AH18,5) -> 0.041 | AJ18: =ROUND(RFR_spot_no_VA!AJ18 + MAX(0.01,Shocks!$E18*ABS(RFR_spot_no_VA!AJ18) )+VA!AJ18,5) -> 0.03804 | AK18: =ROUND(RFR_spot_no_VA!AK18 + MAX(0.01,Shocks!$E18*ABS(RFR_spot_no_VA!AK18) )+VA!AK18,5) -> 0.06316 | AM18: =ROUND(RFR_spot_no_VA!AM18 + MAX(0.01,Shocks!$E18*ABS(RFR_spot_no_VA!AM18) )+VA!AM18,5) -> 0.05589 | AS18: =ROUND(RFR_spot_no_VA!AS18 + MAX(0.01,Shocks!$E18*ABS(RFR_spot_no_VA!AS18) )+VA!AS18,5) -> 0.01223 | BC18: =ROUND(RFR_spot_no_VA!BC18 + MAX(0.01,Shocks!$E18*ABS(RFR_spot_no_VA!BC18) )+VA!BC18,5) -> 0.04855
